2024-04-19 12:35:25,649-INFO-Started server process [71960]
2024-04-19 12:35:25,649-INFO-Waiting for application startup.
2024-04-19 12:35:25,650-INFO-Application startup complete.
2024-04-19 12:38:32,869-INFO-Shutting down
2024-04-19 12:38:32,973-INFO-Waiting for application shutdown.
2024-04-19 12:38:32,974-INFO-Application shutdown complete.
2024-04-19 12:38:32,976-INFO-Finished server process [71960]
2024-04-19 12:38:34,083-INFO-Started server process [72152]
2024-04-19 12:38:34,083-INFO-Waiting for application startup.
2024-04-19 12:38:34,084-INFO-Application startup complete.
2024-04-19 12:45:27,326-ERROR-Exception in ASGI application
Traceback (most recent call last):
  File "/home/thrymr/.local/lib/python3.10/site-packages/uvicorn/protocols/http/httptools_impl.py", line 376, in run_asgi
    result = await app(self.scope, self.receive, self.send)
  File "/home/thrymr/.local/lib/python3.10/site-packages/uvicorn/middleware/proxy_headers.py", line 75, in __call__
    return await self.app(scope, receive, send)
  File "/home/thrymr/.local/lib/python3.10/site-packages/fastapi/applications.py", line 1054, in __call__
    await super().__call__(scope, receive, send)
  File "/home/thrymr/.local/lib/python3.10/site-packages/starlette/applications.py", line 123, in __call__
    await self.middleware_stack(scope, receive, send)
  File "/home/thrymr/.local/lib/python3.10/site-packages/starlette/middleware/errors.py", line 186, in __call__
    raise exc
  File "/home/thrymr/.local/lib/python3.10/site-packages/starlette/middleware/errors.py", line 164, in __call__
    await self.app(scope, receive, _send)
  File "/home/thrymr/.local/lib/python3.10/site-packages/starlette/middleware/cors.py", line 91, in __call__
    await self.simple_response(scope, receive, send, request_headers=headers)
  File "/home/thrymr/.local/lib/python3.10/site-packages/starlette/middleware/cors.py", line 146, in simple_response
    await self.app(scope, receive, send)
  File "/home/thrymr/.local/lib/python3.10/site-packages/starlette/middleware/exceptions.py", line 62, in __call__
    await wrap_app_handling_exceptions(self.app, conn)(scope, receive, send)
  File "/home/thrymr/.local/lib/python3.10/site-packages/starlette/_exception_handler.py", line 64, in wrapped_app
    raise exc
  File "/home/thrymr/.local/lib/python3.10/site-packages/starlette/_exception_handler.py", line 53, in wrapped_app
    await app(scope, receive, sender)
  File "/home/thrymr/.local/lib/python3.10/site-packages/starlette/routing.py", line 758, in __call__
    await self.middleware_stack(scope, receive, send)
  File "/home/thrymr/.local/lib/python3.10/site-packages/starlette/routing.py", line 778, in app
    await route.handle(scope, receive, send)
  File "/home/thrymr/.local/lib/python3.10/site-packages/starlette/routing.py", line 299, in handle
    await self.app(scope, receive, send)
  File "/home/thrymr/.local/lib/python3.10/site-packages/starlette/routing.py", line 79, in app
    await wrap_app_handling_exceptions(app, request)(scope, receive, send)
  File "/home/thrymr/.local/lib/python3.10/site-packages/starlette/_exception_handler.py", line 64, in wrapped_app
    raise exc
  File "/home/thrymr/.local/lib/python3.10/site-packages/starlette/_exception_handler.py", line 53, in wrapped_app
    await app(scope, receive, sender)
  File "/home/thrymr/.local/lib/python3.10/site-packages/starlette/routing.py", line 74, in app
    response = await func(request)
  File "/home/thrymr/.local/lib/python3.10/site-packages/fastapi/routing.py", line 317, in app
    raise FastAPIError(
fastapi.exceptions.FastAPIError: No response object was returned. There's a high chance that the application code is raising an exception and a dependency with yield has a block with a bare except, or a block with except Exception, and is not raising the exception again. Read more about it in the docs: https://fastapi.tiangolo.com/tutorial/dependencies/dependencies-with-yield/#dependencies-with-yield-and-except
2024-04-19 12:49:08,197-INFO-Shutting down
2024-04-19 12:49:08,298-INFO-Waiting for application shutdown.
2024-04-19 12:49:08,298-INFO-Application shutdown complete.
2024-04-19 12:49:08,299-INFO-Finished server process [72152]
2024-04-19 12:49:09,406-INFO-Started server process [72701]
2024-04-19 12:49:09,407-INFO-Waiting for application startup.
2024-04-19 12:49:09,407-INFO-Application startup complete.
2024-04-19 12:49:14,431-ERROR-Exception in ASGI application
Traceback (most recent call last):
  File "/home/thrymr/.local/lib/python3.10/site-packages/uvicorn/protocols/http/httptools_impl.py", line 376, in run_asgi
    result = await app(self.scope, self.receive, self.send)
  File "/home/thrymr/.local/lib/python3.10/site-packages/uvicorn/middleware/proxy_headers.py", line 75, in __call__
    return await self.app(scope, receive, send)
  File "/home/thrymr/.local/lib/python3.10/site-packages/fastapi/applications.py", line 1054, in __call__
    await super().__call__(scope, receive, send)
  File "/home/thrymr/.local/lib/python3.10/site-packages/starlette/applications.py", line 123, in __call__
    await self.middleware_stack(scope, receive, send)
  File "/home/thrymr/.local/lib/python3.10/site-packages/starlette/middleware/errors.py", line 186, in __call__
    raise exc
  File "/home/thrymr/.local/lib/python3.10/site-packages/starlette/middleware/errors.py", line 164, in __call__
    await self.app(scope, receive, _send)
  File "/home/thrymr/.local/lib/python3.10/site-packages/starlette/middleware/cors.py", line 91, in __call__
    await self.simple_response(scope, receive, send, request_headers=headers)
  File "/home/thrymr/.local/lib/python3.10/site-packages/starlette/middleware/cors.py", line 146, in simple_response
    await self.app(scope, receive, send)
  File "/home/thrymr/.local/lib/python3.10/site-packages/starlette/middleware/exceptions.py", line 62, in __call__
    await wrap_app_handling_exceptions(self.app, conn)(scope, receive, send)
  File "/home/thrymr/.local/lib/python3.10/site-packages/starlette/_exception_handler.py", line 64, in wrapped_app
    raise exc
  File "/home/thrymr/.local/lib/python3.10/site-packages/starlette/_exception_handler.py", line 53, in wrapped_app
    await app(scope, receive, sender)
  File "/home/thrymr/.local/lib/python3.10/site-packages/starlette/routing.py", line 758, in __call__
    await self.middleware_stack(scope, receive, send)
  File "/home/thrymr/.local/lib/python3.10/site-packages/starlette/routing.py", line 778, in app
    await route.handle(scope, receive, send)
  File "/home/thrymr/.local/lib/python3.10/site-packages/starlette/routing.py", line 299, in handle
    await self.app(scope, receive, send)
  File "/home/thrymr/.local/lib/python3.10/site-packages/starlette/routing.py", line 79, in app
    await wrap_app_handling_exceptions(app, request)(scope, receive, send)
  File "/home/thrymr/.local/lib/python3.10/site-packages/starlette/_exception_handler.py", line 64, in wrapped_app
    raise exc
  File "/home/thrymr/.local/lib/python3.10/site-packages/starlette/_exception_handler.py", line 53, in wrapped_app
    await app(scope, receive, sender)
  File "/home/thrymr/.local/lib/python3.10/site-packages/starlette/routing.py", line 74, in app
    response = await func(request)
  File "/home/thrymr/.local/lib/python3.10/site-packages/fastapi/routing.py", line 317, in app
    raise FastAPIError(
fastapi.exceptions.FastAPIError: No response object was returned. There's a high chance that the application code is raising an exception and a dependency with yield has a block with a bare except, or a block with except Exception, and is not raising the exception again. Read more about it in the docs: https://fastapi.tiangolo.com/tutorial/dependencies/dependencies-with-yield/#dependencies-with-yield-and-except
2024-04-19 12:50:14,179-INFO-Shutting down
2024-04-19 12:50:14,279-INFO-Waiting for application shutdown.
2024-04-19 12:50:14,280-INFO-Application shutdown complete.
2024-04-19 12:50:14,281-INFO-Finished server process [72701]
2024-04-19 12:50:15,363-INFO-Started server process [72772]
2024-04-19 12:50:15,364-INFO-Waiting for application startup.
2024-04-19 12:50:15,364-INFO-Application startup complete.
2024-04-19 12:50:20,485-ERROR-Exception in ASGI application
Traceback (most recent call last):
  File "/home/thrymr/.local/lib/python3.10/site-packages/uvicorn/protocols/http/httptools_impl.py", line 376, in run_asgi
    result = await app(self.scope, self.receive, self.send)
  File "/home/thrymr/.local/lib/python3.10/site-packages/uvicorn/middleware/proxy_headers.py", line 75, in __call__
    return await self.app(scope, receive, send)
  File "/home/thrymr/.local/lib/python3.10/site-packages/fastapi/applications.py", line 1054, in __call__
    await super().__call__(scope, receive, send)
  File "/home/thrymr/.local/lib/python3.10/site-packages/starlette/applications.py", line 123, in __call__
    await self.middleware_stack(scope, receive, send)
  File "/home/thrymr/.local/lib/python3.10/site-packages/starlette/middleware/errors.py", line 186, in __call__
    raise exc
  File "/home/thrymr/.local/lib/python3.10/site-packages/starlette/middleware/errors.py", line 164, in __call__
    await self.app(scope, receive, _send)
  File "/home/thrymr/.local/lib/python3.10/site-packages/starlette/middleware/cors.py", line 91, in __call__
    await self.simple_response(scope, receive, send, request_headers=headers)
  File "/home/thrymr/.local/lib/python3.10/site-packages/starlette/middleware/cors.py", line 146, in simple_response
    await self.app(scope, receive, send)
  File "/home/thrymr/.local/lib/python3.10/site-packages/starlette/middleware/exceptions.py", line 62, in __call__
    await wrap_app_handling_exceptions(self.app, conn)(scope, receive, send)
  File "/home/thrymr/.local/lib/python3.10/site-packages/starlette/_exception_handler.py", line 64, in wrapped_app
    raise exc
  File "/home/thrymr/.local/lib/python3.10/site-packages/starlette/_exception_handler.py", line 53, in wrapped_app
    await app(scope, receive, sender)
  File "/home/thrymr/.local/lib/python3.10/site-packages/starlette/routing.py", line 758, in __call__
    await self.middleware_stack(scope, receive, send)
  File "/home/thrymr/.local/lib/python3.10/site-packages/starlette/routing.py", line 778, in app
    await route.handle(scope, receive, send)
  File "/home/thrymr/.local/lib/python3.10/site-packages/starlette/routing.py", line 299, in handle
    await self.app(scope, receive, send)
  File "/home/thrymr/.local/lib/python3.10/site-packages/starlette/routing.py", line 79, in app
    await wrap_app_handling_exceptions(app, request)(scope, receive, send)
  File "/home/thrymr/.local/lib/python3.10/site-packages/starlette/_exception_handler.py", line 64, in wrapped_app
    raise exc
  File "/home/thrymr/.local/lib/python3.10/site-packages/starlette/_exception_handler.py", line 53, in wrapped_app
    await app(scope, receive, sender)
  File "/home/thrymr/.local/lib/python3.10/site-packages/starlette/routing.py", line 74, in app
    response = await func(request)
  File "/home/thrymr/.local/lib/python3.10/site-packages/fastapi/routing.py", line 317, in app
    raise FastAPIError(
fastapi.exceptions.FastAPIError: No response object was returned. There's a high chance that the application code is raising an exception and a dependency with yield has a block with a bare except, or a block with except Exception, and is not raising the exception again. Read more about it in the docs: https://fastapi.tiangolo.com/tutorial/dependencies/dependencies-with-yield/#dependencies-with-yield-and-except
2024-04-19 12:51:12,126-INFO-Shutting down
2024-04-19 12:51:12,227-INFO-Waiting for application shutdown.
2024-04-19 12:51:12,228-INFO-Application shutdown complete.
2024-04-19 12:51:12,228-INFO-Finished server process [72772]
2024-04-19 12:51:13,311-INFO-Started server process [72867]
2024-04-19 12:51:13,311-INFO-Waiting for application startup.
2024-04-19 12:51:13,311-INFO-Application startup complete.
2024-04-19 12:51:28,081-ERROR-Exception in ASGI application
Traceback (most recent call last):
  File "/home/thrymr/.local/lib/python3.10/site-packages/uvicorn/protocols/http/httptools_impl.py", line 376, in run_asgi
    result = await app(self.scope, self.receive, self.send)
  File "/home/thrymr/.local/lib/python3.10/site-packages/uvicorn/middleware/proxy_headers.py", line 75, in __call__
    return await self.app(scope, receive, send)
  File "/home/thrymr/.local/lib/python3.10/site-packages/fastapi/applications.py", line 1054, in __call__
    await super().__call__(scope, receive, send)
  File "/home/thrymr/.local/lib/python3.10/site-packages/starlette/applications.py", line 123, in __call__
    await self.middleware_stack(scope, receive, send)
  File "/home/thrymr/.local/lib/python3.10/site-packages/starlette/middleware/errors.py", line 186, in __call__
    raise exc
  File "/home/thrymr/.local/lib/python3.10/site-packages/starlette/middleware/errors.py", line 164, in __call__
    await self.app(scope, receive, _send)
  File "/home/thrymr/.local/lib/python3.10/site-packages/starlette/middleware/cors.py", line 91, in __call__
    await self.simple_response(scope, receive, send, request_headers=headers)
  File "/home/thrymr/.local/lib/python3.10/site-packages/starlette/middleware/cors.py", line 146, in simple_response
    await self.app(scope, receive, send)
  File "/home/thrymr/.local/lib/python3.10/site-packages/starlette/middleware/exceptions.py", line 62, in __call__
    await wrap_app_handling_exceptions(self.app, conn)(scope, receive, send)
  File "/home/thrymr/.local/lib/python3.10/site-packages/starlette/_exception_handler.py", line 64, in wrapped_app
    raise exc
  File "/home/thrymr/.local/lib/python3.10/site-packages/starlette/_exception_handler.py", line 53, in wrapped_app
    await app(scope, receive, sender)
  File "/home/thrymr/.local/lib/python3.10/site-packages/starlette/routing.py", line 758, in __call__
    await self.middleware_stack(scope, receive, send)
  File "/home/thrymr/.local/lib/python3.10/site-packages/starlette/routing.py", line 778, in app
    await route.handle(scope, receive, send)
  File "/home/thrymr/.local/lib/python3.10/site-packages/starlette/routing.py", line 299, in handle
    await self.app(scope, receive, send)
  File "/home/thrymr/.local/lib/python3.10/site-packages/starlette/routing.py", line 79, in app
    await wrap_app_handling_exceptions(app, request)(scope, receive, send)
  File "/home/thrymr/.local/lib/python3.10/site-packages/starlette/_exception_handler.py", line 64, in wrapped_app
    raise exc
  File "/home/thrymr/.local/lib/python3.10/site-packages/starlette/_exception_handler.py", line 53, in wrapped_app
    await app(scope, receive, sender)
  File "/home/thrymr/.local/lib/python3.10/site-packages/starlette/routing.py", line 74, in app
    response = await func(request)
  File "/home/thrymr/.local/lib/python3.10/site-packages/fastapi/routing.py", line 317, in app
    raise FastAPIError(
fastapi.exceptions.FastAPIError: No response object was returned. There's a high chance that the application code is raising an exception and a dependency with yield has a block with a bare except, or a block with except Exception, and is not raising the exception again. Read more about it in the docs: https://fastapi.tiangolo.com/tutorial/dependencies/dependencies-with-yield/#dependencies-with-yield-and-except
2024-04-19 12:52:38,433-INFO-Shutting down
2024-04-19 12:52:38,534-INFO-Waiting for application shutdown.
2024-04-19 12:52:38,534-INFO-Application shutdown complete.
2024-04-19 12:52:38,535-INFO-Finished server process [72867]
2024-04-19 12:52:39,613-INFO-Started server process [72951]
2024-04-19 12:52:39,613-INFO-Waiting for application startup.
2024-04-19 12:52:39,614-INFO-Application startup complete.
2024-04-19 12:52:58,173-ERROR-Exception in ASGI application
Traceback (most recent call last):
  File "/home/thrymr/.local/lib/python3.10/site-packages/uvicorn/protocols/http/httptools_impl.py", line 376, in run_asgi
    result = await app(self.scope, self.receive, self.send)
  File "/home/thrymr/.local/lib/python3.10/site-packages/uvicorn/middleware/proxy_headers.py", line 75, in __call__
    return await self.app(scope, receive, send)
  File "/home/thrymr/.local/lib/python3.10/site-packages/fastapi/applications.py", line 1054, in __call__
    await super().__call__(scope, receive, send)
  File "/home/thrymr/.local/lib/python3.10/site-packages/starlette/applications.py", line 123, in __call__
    await self.middleware_stack(scope, receive, send)
  File "/home/thrymr/.local/lib/python3.10/site-packages/starlette/middleware/errors.py", line 186, in __call__
    raise exc
  File "/home/thrymr/.local/lib/python3.10/site-packages/starlette/middleware/errors.py", line 164, in __call__
    await self.app(scope, receive, _send)
  File "/home/thrymr/.local/lib/python3.10/site-packages/starlette/middleware/cors.py", line 91, in __call__
    await self.simple_response(scope, receive, send, request_headers=headers)
  File "/home/thrymr/.local/lib/python3.10/site-packages/starlette/middleware/cors.py", line 146, in simple_response
    await self.app(scope, receive, send)
  File "/home/thrymr/.local/lib/python3.10/site-packages/starlette/middleware/exceptions.py", line 62, in __call__
    await wrap_app_handling_exceptions(self.app, conn)(scope, receive, send)
  File "/home/thrymr/.local/lib/python3.10/site-packages/starlette/_exception_handler.py", line 64, in wrapped_app
    raise exc
  File "/home/thrymr/.local/lib/python3.10/site-packages/starlette/_exception_handler.py", line 53, in wrapped_app
    await app(scope, receive, sender)
  File "/home/thrymr/.local/lib/python3.10/site-packages/starlette/routing.py", line 758, in __call__
    await self.middleware_stack(scope, receive, send)
  File "/home/thrymr/.local/lib/python3.10/site-packages/starlette/routing.py", line 778, in app
    await route.handle(scope, receive, send)
  File "/home/thrymr/.local/lib/python3.10/site-packages/starlette/routing.py", line 299, in handle
    await self.app(scope, receive, send)
  File "/home/thrymr/.local/lib/python3.10/site-packages/starlette/routing.py", line 79, in app
    await wrap_app_handling_exceptions(app, request)(scope, receive, send)
  File "/home/thrymr/.local/lib/python3.10/site-packages/starlette/_exception_handler.py", line 64, in wrapped_app
    raise exc
  File "/home/thrymr/.local/lib/python3.10/site-packages/starlette/_exception_handler.py", line 53, in wrapped_app
    await app(scope, receive, sender)
  File "/home/thrymr/.local/lib/python3.10/site-packages/starlette/routing.py", line 74, in app
    response = await func(request)
  File "/home/thrymr/.local/lib/python3.10/site-packages/fastapi/routing.py", line 317, in app
    raise FastAPIError(
fastapi.exceptions.FastAPIError: No response object was returned. There's a high chance that the application code is raising an exception and a dependency with yield has a block with a bare except, or a block with except Exception, and is not raising the exception again. Read more about it in the docs: https://fastapi.tiangolo.com/tutorial/dependencies/dependencies-with-yield/#dependencies-with-yield-and-except
2024-04-19 12:53:21,926-INFO-Shutting down
2024-04-19 12:53:22,027-INFO-Waiting for application shutdown.
2024-04-19 12:53:22,027-INFO-Application shutdown complete.
2024-04-19 12:53:22,028-INFO-Finished server process [72951]
2024-04-19 12:53:23,108-INFO-Started server process [73012]
2024-04-19 12:53:23,108-INFO-Waiting for application startup.
2024-04-19 12:53:23,108-INFO-Application startup complete.
2024-04-19 12:53:31,087-ERROR-Exception in ASGI application
Traceback (most recent call last):
  File "/home/thrymr/.local/lib/python3.10/site-packages/uvicorn/protocols/http/httptools_impl.py", line 376, in run_asgi
    result = await app(self.scope, self.receive, self.send)
  File "/home/thrymr/.local/lib/python3.10/site-packages/uvicorn/middleware/proxy_headers.py", line 75, in __call__
    return await self.app(scope, receive, send)
  File "/home/thrymr/.local/lib/python3.10/site-packages/fastapi/applications.py", line 1054, in __call__
    await super().__call__(scope, receive, send)
  File "/home/thrymr/.local/lib/python3.10/site-packages/starlette/applications.py", line 123, in __call__
    await self.middleware_stack(scope, receive, send)
  File "/home/thrymr/.local/lib/python3.10/site-packages/starlette/middleware/errors.py", line 186, in __call__
    raise exc
  File "/home/thrymr/.local/lib/python3.10/site-packages/starlette/middleware/errors.py", line 164, in __call__
    await self.app(scope, receive, _send)
  File "/home/thrymr/.local/lib/python3.10/site-packages/starlette/middleware/cors.py", line 91, in __call__
    await self.simple_response(scope, receive, send, request_headers=headers)
  File "/home/thrymr/.local/lib/python3.10/site-packages/starlette/middleware/cors.py", line 146, in simple_response
    await self.app(scope, receive, send)
  File "/home/thrymr/.local/lib/python3.10/site-packages/starlette/middleware/exceptions.py", line 62, in __call__
    await wrap_app_handling_exceptions(self.app, conn)(scope, receive, send)
  File "/home/thrymr/.local/lib/python3.10/site-packages/starlette/_exception_handler.py", line 64, in wrapped_app
    raise exc
  File "/home/thrymr/.local/lib/python3.10/site-packages/starlette/_exception_handler.py", line 53, in wrapped_app
    await app(scope, receive, sender)
  File "/home/thrymr/.local/lib/python3.10/site-packages/starlette/routing.py", line 758, in __call__
    await self.middleware_stack(scope, receive, send)
  File "/home/thrymr/.local/lib/python3.10/site-packages/starlette/routing.py", line 778, in app
    await route.handle(scope, receive, send)
  File "/home/thrymr/.local/lib/python3.10/site-packages/starlette/routing.py", line 299, in handle
    await self.app(scope, receive, send)
  File "/home/thrymr/.local/lib/python3.10/site-packages/starlette/routing.py", line 79, in app
    await wrap_app_handling_exceptions(app, request)(scope, receive, send)
  File "/home/thrymr/.local/lib/python3.10/site-packages/starlette/_exception_handler.py", line 64, in wrapped_app
    raise exc
  File "/home/thrymr/.local/lib/python3.10/site-packages/starlette/_exception_handler.py", line 53, in wrapped_app
    await app(scope, receive, sender)
  File "/home/thrymr/.local/lib/python3.10/site-packages/starlette/routing.py", line 74, in app
    response = await func(request)
  File "/home/thrymr/.local/lib/python3.10/site-packages/fastapi/routing.py", line 317, in app
    raise FastAPIError(
fastapi.exceptions.FastAPIError: No response object was returned. There's a high chance that the application code is raising an exception and a dependency with yield has a block with a bare except, or a block with except Exception, and is not raising the exception again. Read more about it in the docs: https://fastapi.tiangolo.com/tutorial/dependencies/dependencies-with-yield/#dependencies-with-yield-and-except
2024-04-19 12:53:55,683-ERROR-Exception in ASGI application
Traceback (most recent call last):
  File "/home/thrymr/.local/lib/python3.10/site-packages/uvicorn/protocols/http/httptools_impl.py", line 376, in run_asgi
    result = await app(self.scope, self.receive, self.send)
  File "/home/thrymr/.local/lib/python3.10/site-packages/uvicorn/middleware/proxy_headers.py", line 75, in __call__
    return await self.app(scope, receive, send)
  File "/home/thrymr/.local/lib/python3.10/site-packages/fastapi/applications.py", line 1054, in __call__
    await super().__call__(scope, receive, send)
  File "/home/thrymr/.local/lib/python3.10/site-packages/starlette/applications.py", line 123, in __call__
    await self.middleware_stack(scope, receive, send)
  File "/home/thrymr/.local/lib/python3.10/site-packages/starlette/middleware/errors.py", line 186, in __call__
    raise exc
  File "/home/thrymr/.local/lib/python3.10/site-packages/starlette/middleware/errors.py", line 164, in __call__
    await self.app(scope, receive, _send)
  File "/home/thrymr/.local/lib/python3.10/site-packages/starlette/middleware/cors.py", line 91, in __call__
    await self.simple_response(scope, receive, send, request_headers=headers)
  File "/home/thrymr/.local/lib/python3.10/site-packages/starlette/middleware/cors.py", line 146, in simple_response
    await self.app(scope, receive, send)
  File "/home/thrymr/.local/lib/python3.10/site-packages/starlette/middleware/exceptions.py", line 62, in __call__
    await wrap_app_handling_exceptions(self.app, conn)(scope, receive, send)
  File "/home/thrymr/.local/lib/python3.10/site-packages/starlette/_exception_handler.py", line 64, in wrapped_app
    raise exc
  File "/home/thrymr/.local/lib/python3.10/site-packages/starlette/_exception_handler.py", line 53, in wrapped_app
    await app(scope, receive, sender)
  File "/home/thrymr/.local/lib/python3.10/site-packages/starlette/routing.py", line 758, in __call__
    await self.middleware_stack(scope, receive, send)
  File "/home/thrymr/.local/lib/python3.10/site-packages/starlette/routing.py", line 778, in app
    await route.handle(scope, receive, send)
  File "/home/thrymr/.local/lib/python3.10/site-packages/starlette/routing.py", line 299, in handle
    await self.app(scope, receive, send)
  File "/home/thrymr/.local/lib/python3.10/site-packages/starlette/routing.py", line 79, in app
    await wrap_app_handling_exceptions(app, request)(scope, receive, send)
  File "/home/thrymr/.local/lib/python3.10/site-packages/starlette/_exception_handler.py", line 64, in wrapped_app
    raise exc
  File "/home/thrymr/.local/lib/python3.10/site-packages/starlette/_exception_handler.py", line 53, in wrapped_app
    await app(scope, receive, sender)
  File "/home/thrymr/.local/lib/python3.10/site-packages/starlette/routing.py", line 74, in app
    response = await func(request)
  File "/home/thrymr/.local/lib/python3.10/site-packages/fastapi/routing.py", line 317, in app
    raise FastAPIError(
fastapi.exceptions.FastAPIError: No response object was returned. There's a high chance that the application code is raising an exception and a dependency with yield has a block with a bare except, or a block with except Exception, and is not raising the exception again. Read more about it in the docs: https://fastapi.tiangolo.com/tutorial/dependencies/dependencies-with-yield/#dependencies-with-yield-and-except
2024-04-19 12:55:45,789-INFO-Shutting down
2024-04-19 12:55:45,890-INFO-Waiting for application shutdown.
2024-04-19 12:55:45,891-INFO-Application shutdown complete.
2024-04-19 12:55:45,891-INFO-Finished server process [73012]
2024-04-19 12:55:46,965-INFO-Started server process [73154]
2024-04-19 12:55:46,965-INFO-Waiting for application startup.
2024-04-19 12:55:46,966-INFO-Application startup complete.
2024-04-19 12:56:24,912-ERROR-Exception in ASGI application
Traceback (most recent call last):
  File "/home/thrymr/.local/lib/python3.10/site-packages/uvicorn/protocols/http/httptools_impl.py", line 376, in run_asgi
    result = await app(self.scope, self.receive, self.send)
  File "/home/thrymr/.local/lib/python3.10/site-packages/uvicorn/middleware/proxy_headers.py", line 75, in __call__
    return await self.app(scope, receive, send)
  File "/home/thrymr/.local/lib/python3.10/site-packages/fastapi/applications.py", line 1054, in __call__
    await super().__call__(scope, receive, send)
  File "/home/thrymr/.local/lib/python3.10/site-packages/starlette/applications.py", line 123, in __call__
    await self.middleware_stack(scope, receive, send)
  File "/home/thrymr/.local/lib/python3.10/site-packages/starlette/middleware/errors.py", line 186, in __call__
    raise exc
  File "/home/thrymr/.local/lib/python3.10/site-packages/starlette/middleware/errors.py", line 164, in __call__
    await self.app(scope, receive, _send)
  File "/home/thrymr/.local/lib/python3.10/site-packages/starlette/middleware/cors.py", line 91, in __call__
    await self.simple_response(scope, receive, send, request_headers=headers)
  File "/home/thrymr/.local/lib/python3.10/site-packages/starlette/middleware/cors.py", line 146, in simple_response
    await self.app(scope, receive, send)
  File "/home/thrymr/.local/lib/python3.10/site-packages/starlette/middleware/exceptions.py", line 62, in __call__
    await wrap_app_handling_exceptions(self.app, conn)(scope, receive, send)
  File "/home/thrymr/.local/lib/python3.10/site-packages/starlette/_exception_handler.py", line 64, in wrapped_app
    raise exc
  File "/home/thrymr/.local/lib/python3.10/site-packages/starlette/_exception_handler.py", line 53, in wrapped_app
    await app(scope, receive, sender)
  File "/home/thrymr/.local/lib/python3.10/site-packages/starlette/routing.py", line 758, in __call__
    await self.middleware_stack(scope, receive, send)
  File "/home/thrymr/.local/lib/python3.10/site-packages/starlette/routing.py", line 778, in app
    await route.handle(scope, receive, send)
  File "/home/thrymr/.local/lib/python3.10/site-packages/starlette/routing.py", line 299, in handle
    await self.app(scope, receive, send)
  File "/home/thrymr/.local/lib/python3.10/site-packages/starlette/routing.py", line 79, in app
    await wrap_app_handling_exceptions(app, request)(scope, receive, send)
  File "/home/thrymr/.local/lib/python3.10/site-packages/starlette/_exception_handler.py", line 64, in wrapped_app
    raise exc
  File "/home/thrymr/.local/lib/python3.10/site-packages/starlette/_exception_handler.py", line 53, in wrapped_app
    await app(scope, receive, sender)
  File "/home/thrymr/.local/lib/python3.10/site-packages/starlette/routing.py", line 74, in app
    response = await func(request)
  File "/home/thrymr/.local/lib/python3.10/site-packages/fastapi/routing.py", line 317, in app
    raise FastAPIError(
fastapi.exceptions.FastAPIError: No response object was returned. There's a high chance that the application code is raising an exception and a dependency with yield has a block with a bare except, or a block with except Exception, and is not raising the exception again. Read more about it in the docs: https://fastapi.tiangolo.com/tutorial/dependencies/dependencies-with-yield/#dependencies-with-yield-and-except
2024-04-19 12:57:39,058-INFO-Shutting down
2024-04-19 12:57:39,159-INFO-Waiting for application shutdown.
2024-04-19 12:57:39,159-INFO-Application shutdown complete.
2024-04-19 12:57:39,160-INFO-Finished server process [73154]
2024-04-19 12:57:40,242-INFO-Started server process [73278]
2024-04-19 12:57:40,243-INFO-Waiting for application startup.
2024-04-19 12:57:40,243-INFO-Application startup complete.
2024-04-19 12:57:47,848-ERROR-Exception in ASGI application
Traceback (most recent call last):
  File "/home/thrymr/.local/lib/python3.10/site-packages/uvicorn/protocols/http/httptools_impl.py", line 376, in run_asgi
    result = await app(self.scope, self.receive, self.send)
  File "/home/thrymr/.local/lib/python3.10/site-packages/uvicorn/middleware/proxy_headers.py", line 75, in __call__
    return await self.app(scope, receive, send)
  File "/home/thrymr/.local/lib/python3.10/site-packages/fastapi/applications.py", line 1054, in __call__
    await super().__call__(scope, receive, send)
  File "/home/thrymr/.local/lib/python3.10/site-packages/starlette/applications.py", line 123, in __call__
    await self.middleware_stack(scope, receive, send)
  File "/home/thrymr/.local/lib/python3.10/site-packages/starlette/middleware/errors.py", line 186, in __call__
    raise exc
  File "/home/thrymr/.local/lib/python3.10/site-packages/starlette/middleware/errors.py", line 164, in __call__
    await self.app(scope, receive, _send)
  File "/home/thrymr/.local/lib/python3.10/site-packages/starlette/middleware/cors.py", line 91, in __call__
    await self.simple_response(scope, receive, send, request_headers=headers)
  File "/home/thrymr/.local/lib/python3.10/site-packages/starlette/middleware/cors.py", line 146, in simple_response
    await self.app(scope, receive, send)
  File "/home/thrymr/.local/lib/python3.10/site-packages/starlette/middleware/exceptions.py", line 62, in __call__
    await wrap_app_handling_exceptions(self.app, conn)(scope, receive, send)
  File "/home/thrymr/.local/lib/python3.10/site-packages/starlette/_exception_handler.py", line 64, in wrapped_app
    raise exc
  File "/home/thrymr/.local/lib/python3.10/site-packages/starlette/_exception_handler.py", line 53, in wrapped_app
    await app(scope, receive, sender)
  File "/home/thrymr/.local/lib/python3.10/site-packages/starlette/routing.py", line 758, in __call__
    await self.middleware_stack(scope, receive, send)
  File "/home/thrymr/.local/lib/python3.10/site-packages/starlette/routing.py", line 778, in app
    await route.handle(scope, receive, send)
  File "/home/thrymr/.local/lib/python3.10/site-packages/starlette/routing.py", line 299, in handle
    await self.app(scope, receive, send)
  File "/home/thrymr/.local/lib/python3.10/site-packages/starlette/routing.py", line 79, in app
    await wrap_app_handling_exceptions(app, request)(scope, receive, send)
  File "/home/thrymr/.local/lib/python3.10/site-packages/starlette/_exception_handler.py", line 64, in wrapped_app
    raise exc
  File "/home/thrymr/.local/lib/python3.10/site-packages/starlette/_exception_handler.py", line 53, in wrapped_app
    await app(scope, receive, sender)
  File "/home/thrymr/.local/lib/python3.10/site-packages/starlette/routing.py", line 74, in app
    response = await func(request)
  File "/home/thrymr/.local/lib/python3.10/site-packages/fastapi/routing.py", line 317, in app
    raise FastAPIError(
fastapi.exceptions.FastAPIError: No response object was returned. There's a high chance that the application code is raising an exception and a dependency with yield has a block with a bare except, or a block with except Exception, and is not raising the exception again. Read more about it in the docs: https://fastapi.tiangolo.com/tutorial/dependencies/dependencies-with-yield/#dependencies-with-yield-and-except
2024-04-19 12:57:59,294-INFO-Shutting down
2024-04-19 12:57:59,395-INFO-Waiting for application shutdown.
2024-04-19 12:57:59,395-INFO-Application shutdown complete.
2024-04-19 12:57:59,396-INFO-Finished server process [73278]
2024-04-19 12:58:00,481-INFO-Started server process [73311]
2024-04-19 12:58:00,481-INFO-Waiting for application startup.
2024-04-19 12:58:00,481-INFO-Application startup complete.
2024-04-19 12:58:05,068-ERROR-Exception in ASGI application
Traceback (most recent call last):
  File "/home/thrymr/.local/lib/python3.10/site-packages/uvicorn/protocols/http/httptools_impl.py", line 376, in run_asgi
    result = await app(self.scope, self.receive, self.send)
  File "/home/thrymr/.local/lib/python3.10/site-packages/uvicorn/middleware/proxy_headers.py", line 75, in __call__
    return await self.app(scope, receive, send)
  File "/home/thrymr/.local/lib/python3.10/site-packages/fastapi/applications.py", line 1054, in __call__
    await super().__call__(scope, receive, send)
  File "/home/thrymr/.local/lib/python3.10/site-packages/starlette/applications.py", line 123, in __call__
    await self.middleware_stack(scope, receive, send)
  File "/home/thrymr/.local/lib/python3.10/site-packages/starlette/middleware/errors.py", line 186, in __call__
    raise exc
  File "/home/thrymr/.local/lib/python3.10/site-packages/starlette/middleware/errors.py", line 164, in __call__
    await self.app(scope, receive, _send)
  File "/home/thrymr/.local/lib/python3.10/site-packages/starlette/middleware/cors.py", line 91, in __call__
    await self.simple_response(scope, receive, send, request_headers=headers)
  File "/home/thrymr/.local/lib/python3.10/site-packages/starlette/middleware/cors.py", line 146, in simple_response
    await self.app(scope, receive, send)
  File "/home/thrymr/.local/lib/python3.10/site-packages/starlette/middleware/exceptions.py", line 62, in __call__
    await wrap_app_handling_exceptions(self.app, conn)(scope, receive, send)
  File "/home/thrymr/.local/lib/python3.10/site-packages/starlette/_exception_handler.py", line 64, in wrapped_app
    raise exc
  File "/home/thrymr/.local/lib/python3.10/site-packages/starlette/_exception_handler.py", line 53, in wrapped_app
    await app(scope, receive, sender)
  File "/home/thrymr/.local/lib/python3.10/site-packages/starlette/routing.py", line 758, in __call__
    await self.middleware_stack(scope, receive, send)
  File "/home/thrymr/.local/lib/python3.10/site-packages/starlette/routing.py", line 778, in app
    await route.handle(scope, receive, send)
  File "/home/thrymr/.local/lib/python3.10/site-packages/starlette/routing.py", line 299, in handle
    await self.app(scope, receive, send)
  File "/home/thrymr/.local/lib/python3.10/site-packages/starlette/routing.py", line 79, in app
    await wrap_app_handling_exceptions(app, request)(scope, receive, send)
  File "/home/thrymr/.local/lib/python3.10/site-packages/starlette/_exception_handler.py", line 64, in wrapped_app
    raise exc
  File "/home/thrymr/.local/lib/python3.10/site-packages/starlette/_exception_handler.py", line 53, in wrapped_app
    await app(scope, receive, sender)
  File "/home/thrymr/.local/lib/python3.10/site-packages/starlette/routing.py", line 74, in app
    response = await func(request)
  File "/home/thrymr/.local/lib/python3.10/site-packages/fastapi/routing.py", line 317, in app
    raise FastAPIError(
fastapi.exceptions.FastAPIError: No response object was returned. There's a high chance that the application code is raising an exception and a dependency with yield has a block with a bare except, or a block with except Exception, and is not raising the exception again. Read more about it in the docs: https://fastapi.tiangolo.com/tutorial/dependencies/dependencies-with-yield/#dependencies-with-yield-and-except
2024-04-19 12:59:56,194-INFO-Shutting down
2024-04-19 12:59:56,294-INFO-Waiting for application shutdown.
2024-04-19 12:59:56,295-INFO-Application shutdown complete.
2024-04-19 12:59:56,296-INFO-Finished server process [73311]
2024-04-19 12:59:57,380-INFO-Started server process [73419]
2024-04-19 12:59:57,380-INFO-Waiting for application startup.
2024-04-19 12:59:57,381-INFO-Application startup complete.
2024-04-19 13:00:04,016-ERROR-Exception in ASGI application
Traceback (most recent call last):
  File "/home/thrymr/.local/lib/python3.10/site-packages/uvicorn/protocols/http/httptools_impl.py", line 376, in run_asgi
    result = await app(self.scope, self.receive, self.send)
  File "/home/thrymr/.local/lib/python3.10/site-packages/uvicorn/middleware/proxy_headers.py", line 75, in __call__
    return await self.app(scope, receive, send)
  File "/home/thrymr/.local/lib/python3.10/site-packages/fastapi/applications.py", line 1054, in __call__
    await super().__call__(scope, receive, send)
  File "/home/thrymr/.local/lib/python3.10/site-packages/starlette/applications.py", line 123, in __call__
    await self.middleware_stack(scope, receive, send)
  File "/home/thrymr/.local/lib/python3.10/site-packages/starlette/middleware/errors.py", line 186, in __call__
    raise exc
  File "/home/thrymr/.local/lib/python3.10/site-packages/starlette/middleware/errors.py", line 164, in __call__
    await self.app(scope, receive, _send)
  File "/home/thrymr/.local/lib/python3.10/site-packages/starlette/middleware/cors.py", line 91, in __call__
    await self.simple_response(scope, receive, send, request_headers=headers)
  File "/home/thrymr/.local/lib/python3.10/site-packages/starlette/middleware/cors.py", line 146, in simple_response
    await self.app(scope, receive, send)
  File "/home/thrymr/.local/lib/python3.10/site-packages/starlette/middleware/exceptions.py", line 62, in __call__
    await wrap_app_handling_exceptions(self.app, conn)(scope, receive, send)
  File "/home/thrymr/.local/lib/python3.10/site-packages/starlette/_exception_handler.py", line 64, in wrapped_app
    raise exc
  File "/home/thrymr/.local/lib/python3.10/site-packages/starlette/_exception_handler.py", line 53, in wrapped_app
    await app(scope, receive, sender)
  File "/home/thrymr/.local/lib/python3.10/site-packages/starlette/routing.py", line 758, in __call__
    await self.middleware_stack(scope, receive, send)
  File "/home/thrymr/.local/lib/python3.10/site-packages/starlette/routing.py", line 778, in app
    await route.handle(scope, receive, send)
  File "/home/thrymr/.local/lib/python3.10/site-packages/starlette/routing.py", line 299, in handle
    await self.app(scope, receive, send)
  File "/home/thrymr/.local/lib/python3.10/site-packages/starlette/routing.py", line 79, in app
    await wrap_app_handling_exceptions(app, request)(scope, receive, send)
  File "/home/thrymr/.local/lib/python3.10/site-packages/starlette/_exception_handler.py", line 64, in wrapped_app
    raise exc
  File "/home/thrymr/.local/lib/python3.10/site-packages/starlette/_exception_handler.py", line 53, in wrapped_app
    await app(scope, receive, sender)
  File "/home/thrymr/.local/lib/python3.10/site-packages/starlette/routing.py", line 74, in app
    response = await func(request)
  File "/home/thrymr/.local/lib/python3.10/site-packages/fastapi/routing.py", line 317, in app
    raise FastAPIError(
fastapi.exceptions.FastAPIError: No response object was returned. There's a high chance that the application code is raising an exception and a dependency with yield has a block with a bare except, or a block with except Exception, and is not raising the exception again. Read more about it in the docs: https://fastapi.tiangolo.com/tutorial/dependencies/dependencies-with-yield/#dependencies-with-yield-and-except
2024-04-19 13:00:52,827-INFO-Shutting down
2024-04-19 13:00:52,928-INFO-Waiting for application shutdown.
2024-04-19 13:00:52,929-INFO-Application shutdown complete.
2024-04-19 13:00:52,929-INFO-Finished server process [73419]
2024-04-19 13:00:54,003-INFO-Started server process [73478]
2024-04-19 13:00:54,003-INFO-Waiting for application startup.
2024-04-19 13:00:54,003-INFO-Application startup complete.
2024-04-19 13:01:02,416-ERROR-Exception in ASGI application
Traceback (most recent call last):
  File "/home/thrymr/.local/lib/python3.10/site-packages/uvicorn/protocols/http/httptools_impl.py", line 376, in run_asgi
    result = await app(self.scope, self.receive, self.send)
  File "/home/thrymr/.local/lib/python3.10/site-packages/uvicorn/middleware/proxy_headers.py", line 75, in __call__
    return await self.app(scope, receive, send)
  File "/home/thrymr/.local/lib/python3.10/site-packages/fastapi/applications.py", line 1054, in __call__
    await super().__call__(scope, receive, send)
  File "/home/thrymr/.local/lib/python3.10/site-packages/starlette/applications.py", line 123, in __call__
    await self.middleware_stack(scope, receive, send)
  File "/home/thrymr/.local/lib/python3.10/site-packages/starlette/middleware/errors.py", line 186, in __call__
    raise exc
  File "/home/thrymr/.local/lib/python3.10/site-packages/starlette/middleware/errors.py", line 164, in __call__
    await self.app(scope, receive, _send)
  File "/home/thrymr/.local/lib/python3.10/site-packages/starlette/middleware/cors.py", line 91, in __call__
    await self.simple_response(scope, receive, send, request_headers=headers)
  File "/home/thrymr/.local/lib/python3.10/site-packages/starlette/middleware/cors.py", line 146, in simple_response
    await self.app(scope, receive, send)
  File "/home/thrymr/.local/lib/python3.10/site-packages/starlette/middleware/exceptions.py", line 62, in __call__
    await wrap_app_handling_exceptions(self.app, conn)(scope, receive, send)
  File "/home/thrymr/.local/lib/python3.10/site-packages/starlette/_exception_handler.py", line 64, in wrapped_app
    raise exc
  File "/home/thrymr/.local/lib/python3.10/site-packages/starlette/_exception_handler.py", line 53, in wrapped_app
    await app(scope, receive, sender)
  File "/home/thrymr/.local/lib/python3.10/site-packages/starlette/routing.py", line 758, in __call__
    await self.middleware_stack(scope, receive, send)
  File "/home/thrymr/.local/lib/python3.10/site-packages/starlette/routing.py", line 778, in app
    await route.handle(scope, receive, send)
  File "/home/thrymr/.local/lib/python3.10/site-packages/starlette/routing.py", line 299, in handle
    await self.app(scope, receive, send)
  File "/home/thrymr/.local/lib/python3.10/site-packages/starlette/routing.py", line 79, in app
    await wrap_app_handling_exceptions(app, request)(scope, receive, send)
  File "/home/thrymr/.local/lib/python3.10/site-packages/starlette/_exception_handler.py", line 64, in wrapped_app
    raise exc
  File "/home/thrymr/.local/lib/python3.10/site-packages/starlette/_exception_handler.py", line 53, in wrapped_app
    await app(scope, receive, sender)
  File "/home/thrymr/.local/lib/python3.10/site-packages/starlette/routing.py", line 74, in app
    response = await func(request)
  File "/home/thrymr/.local/lib/python3.10/site-packages/fastapi/routing.py", line 317, in app
    raise FastAPIError(
fastapi.exceptions.FastAPIError: No response object was returned. There's a high chance that the application code is raising an exception and a dependency with yield has a block with a bare except, or a block with except Exception, and is not raising the exception again. Read more about it in the docs: https://fastapi.tiangolo.com/tutorial/dependencies/dependencies-with-yield/#dependencies-with-yield-and-except
2024-04-19 13:01:27,092-INFO-Shutting down
2024-04-19 13:01:27,193-INFO-Waiting for application shutdown.
2024-04-19 13:01:27,193-INFO-Application shutdown complete.
2024-04-19 13:01:27,194-INFO-Finished server process [73478]
2024-04-19 13:05:41,292-INFO-Started server process [73722]
2024-04-19 13:05:41,292-INFO-Waiting for application startup.
2024-04-19 13:05:41,292-INFO-Application startup complete.
2024-04-19 13:05:50,319-ERROR-Exception in ASGI application
Traceback (most recent call last):
  File "/home/thrymr/.local/lib/python3.10/site-packages/uvicorn/protocols/http/httptools_impl.py", line 376, in run_asgi
    result = await app(self.scope, self.receive, self.send)
  File "/home/thrymr/.local/lib/python3.10/site-packages/uvicorn/middleware/proxy_headers.py", line 75, in __call__
    return await self.app(scope, receive, send)
  File "/home/thrymr/.local/lib/python3.10/site-packages/fastapi/applications.py", line 1054, in __call__
    await super().__call__(scope, receive, send)
  File "/home/thrymr/.local/lib/python3.10/site-packages/starlette/applications.py", line 123, in __call__
    await self.middleware_stack(scope, receive, send)
  File "/home/thrymr/.local/lib/python3.10/site-packages/starlette/middleware/errors.py", line 186, in __call__
    raise exc
  File "/home/thrymr/.local/lib/python3.10/site-packages/starlette/middleware/errors.py", line 164, in __call__
    await self.app(scope, receive, _send)
  File "/home/thrymr/.local/lib/python3.10/site-packages/starlette/middleware/cors.py", line 91, in __call__
    await self.simple_response(scope, receive, send, request_headers=headers)
  File "/home/thrymr/.local/lib/python3.10/site-packages/starlette/middleware/cors.py", line 146, in simple_response
    await self.app(scope, receive, send)
  File "/home/thrymr/.local/lib/python3.10/site-packages/starlette/middleware/exceptions.py", line 62, in __call__
    await wrap_app_handling_exceptions(self.app, conn)(scope, receive, send)
  File "/home/thrymr/.local/lib/python3.10/site-packages/starlette/_exception_handler.py", line 64, in wrapped_app
    raise exc
  File "/home/thrymr/.local/lib/python3.10/site-packages/starlette/_exception_handler.py", line 53, in wrapped_app
    await app(scope, receive, sender)
  File "/home/thrymr/.local/lib/python3.10/site-packages/starlette/routing.py", line 758, in __call__
    await self.middleware_stack(scope, receive, send)
  File "/home/thrymr/.local/lib/python3.10/site-packages/starlette/routing.py", line 778, in app
    await route.handle(scope, receive, send)
  File "/home/thrymr/.local/lib/python3.10/site-packages/starlette/routing.py", line 299, in handle
    await self.app(scope, receive, send)
  File "/home/thrymr/.local/lib/python3.10/site-packages/starlette/routing.py", line 79, in app
    await wrap_app_handling_exceptions(app, request)(scope, receive, send)
  File "/home/thrymr/.local/lib/python3.10/site-packages/starlette/_exception_handler.py", line 64, in wrapped_app
    raise exc
  File "/home/thrymr/.local/lib/python3.10/site-packages/starlette/_exception_handler.py", line 53, in wrapped_app
    await app(scope, receive, sender)
  File "/home/thrymr/.local/lib/python3.10/site-packages/starlette/routing.py", line 74, in app
    response = await func(request)
  File "/home/thrymr/.local/lib/python3.10/site-packages/fastapi/routing.py", line 317, in app
    raise FastAPIError(
fastapi.exceptions.FastAPIError: No response object was returned. There's a high chance that the application code is raising an exception and a dependency with yield has a block with a bare except, or a block with except Exception, and is not raising the exception again. Read more about it in the docs: https://fastapi.tiangolo.com/tutorial/dependencies/dependencies-with-yield/#dependencies-with-yield-and-except
2024-04-19 13:07:10,925-INFO-Shutting down
2024-04-19 13:07:11,026-INFO-Waiting for application shutdown.
2024-04-19 13:07:11,026-INFO-Application shutdown complete.
2024-04-19 13:07:11,027-INFO-Finished server process [73722]
2024-04-19 13:07:12,190-INFO-Started server process [73870]
2024-04-19 13:07:12,190-INFO-Waiting for application startup.
2024-04-19 13:07:12,191-INFO-Application startup complete.
2024-04-19 13:07:14,910-ERROR-Exception in ASGI application
Traceback (most recent call last):
  File "/home/thrymr/.local/lib/python3.10/site-packages/uvicorn/protocols/http/httptools_impl.py", line 376, in run_asgi
    result = await app(self.scope, self.receive, self.send)
  File "/home/thrymr/.local/lib/python3.10/site-packages/uvicorn/middleware/proxy_headers.py", line 75, in __call__
    return await self.app(scope, receive, send)
  File "/home/thrymr/.local/lib/python3.10/site-packages/fastapi/applications.py", line 1054, in __call__
    await super().__call__(scope, receive, send)
  File "/home/thrymr/.local/lib/python3.10/site-packages/starlette/applications.py", line 123, in __call__
    await self.middleware_stack(scope, receive, send)
  File "/home/thrymr/.local/lib/python3.10/site-packages/starlette/middleware/errors.py", line 186, in __call__
    raise exc
  File "/home/thrymr/.local/lib/python3.10/site-packages/starlette/middleware/errors.py", line 164, in __call__
    await self.app(scope, receive, _send)
  File "/home/thrymr/.local/lib/python3.10/site-packages/starlette/middleware/cors.py", line 91, in __call__
    await self.simple_response(scope, receive, send, request_headers=headers)
  File "/home/thrymr/.local/lib/python3.10/site-packages/starlette/middleware/cors.py", line 146, in simple_response
    await self.app(scope, receive, send)
  File "/home/thrymr/.local/lib/python3.10/site-packages/starlette/middleware/exceptions.py", line 62, in __call__
    await wrap_app_handling_exceptions(self.app, conn)(scope, receive, send)
  File "/home/thrymr/.local/lib/python3.10/site-packages/starlette/_exception_handler.py", line 64, in wrapped_app
    raise exc
  File "/home/thrymr/.local/lib/python3.10/site-packages/starlette/_exception_handler.py", line 53, in wrapped_app
    await app(scope, receive, sender)
  File "/home/thrymr/.local/lib/python3.10/site-packages/starlette/routing.py", line 758, in __call__
    await self.middleware_stack(scope, receive, send)
  File "/home/thrymr/.local/lib/python3.10/site-packages/starlette/routing.py", line 778, in app
    await route.handle(scope, receive, send)
  File "/home/thrymr/.local/lib/python3.10/site-packages/starlette/routing.py", line 299, in handle
    await self.app(scope, receive, send)
  File "/home/thrymr/.local/lib/python3.10/site-packages/starlette/routing.py", line 79, in app
    await wrap_app_handling_exceptions(app, request)(scope, receive, send)
  File "/home/thrymr/.local/lib/python3.10/site-packages/starlette/_exception_handler.py", line 64, in wrapped_app
    raise exc
  File "/home/thrymr/.local/lib/python3.10/site-packages/starlette/_exception_handler.py", line 53, in wrapped_app
    await app(scope, receive, sender)
  File "/home/thrymr/.local/lib/python3.10/site-packages/starlette/routing.py", line 74, in app
    response = await func(request)
  File "/home/thrymr/.local/lib/python3.10/site-packages/fastapi/routing.py", line 317, in app
    raise FastAPIError(
fastapi.exceptions.FastAPIError: No response object was returned. There's a high chance that the application code is raising an exception and a dependency with yield has a block with a bare except, or a block with except Exception, and is not raising the exception again. Read more about it in the docs: https://fastapi.tiangolo.com/tutorial/dependencies/dependencies-with-yield/#dependencies-with-yield-and-except
2024-04-19 13:07:41,364-INFO-Shutting down
2024-04-19 13:07:41,465-INFO-Waiting for application shutdown.
2024-04-19 13:07:41,465-INFO-Application shutdown complete.
2024-04-19 13:07:41,465-INFO-Finished server process [73870]
2024-04-19 13:07:42,583-INFO-Started server process [74290]
2024-04-19 13:07:42,583-INFO-Waiting for application startup.
2024-04-19 13:07:42,583-INFO-Application startup complete.
2024-04-19 13:08:06,708-ERROR-Exception in ASGI application
Traceback (most recent call last):
  File "/home/thrymr/.local/lib/python3.10/site-packages/uvicorn/protocols/http/httptools_impl.py", line 376, in run_asgi
    result = await app(self.scope, self.receive, self.send)
  File "/home/thrymr/.local/lib/python3.10/site-packages/uvicorn/middleware/proxy_headers.py", line 75, in __call__
    return await self.app(scope, receive, send)
  File "/home/thrymr/.local/lib/python3.10/site-packages/fastapi/applications.py", line 1054, in __call__
    await super().__call__(scope, receive, send)
  File "/home/thrymr/.local/lib/python3.10/site-packages/starlette/applications.py", line 123, in __call__
    await self.middleware_stack(scope, receive, send)
  File "/home/thrymr/.local/lib/python3.10/site-packages/starlette/middleware/errors.py", line 186, in __call__
    raise exc
  File "/home/thrymr/.local/lib/python3.10/site-packages/starlette/middleware/errors.py", line 164, in __call__
    await self.app(scope, receive, _send)
  File "/home/thrymr/.local/lib/python3.10/site-packages/starlette/middleware/cors.py", line 91, in __call__
    await self.simple_response(scope, receive, send, request_headers=headers)
  File "/home/thrymr/.local/lib/python3.10/site-packages/starlette/middleware/cors.py", line 146, in simple_response
    await self.app(scope, receive, send)
  File "/home/thrymr/.local/lib/python3.10/site-packages/starlette/middleware/exceptions.py", line 62, in __call__
    await wrap_app_handling_exceptions(self.app, conn)(scope, receive, send)
  File "/home/thrymr/.local/lib/python3.10/site-packages/starlette/_exception_handler.py", line 64, in wrapped_app
    raise exc
  File "/home/thrymr/.local/lib/python3.10/site-packages/starlette/_exception_handler.py", line 53, in wrapped_app
    await app(scope, receive, sender)
  File "/home/thrymr/.local/lib/python3.10/site-packages/starlette/routing.py", line 758, in __call__
    await self.middleware_stack(scope, receive, send)
  File "/home/thrymr/.local/lib/python3.10/site-packages/starlette/routing.py", line 778, in app
    await route.handle(scope, receive, send)
  File "/home/thrymr/.local/lib/python3.10/site-packages/starlette/routing.py", line 299, in handle
    await self.app(scope, receive, send)
  File "/home/thrymr/.local/lib/python3.10/site-packages/starlette/routing.py", line 79, in app
    await wrap_app_handling_exceptions(app, request)(scope, receive, send)
  File "/home/thrymr/.local/lib/python3.10/site-packages/starlette/_exception_handler.py", line 64, in wrapped_app
    raise exc
  File "/home/thrymr/.local/lib/python3.10/site-packages/starlette/_exception_handler.py", line 53, in wrapped_app
    await app(scope, receive, sender)
  File "/home/thrymr/.local/lib/python3.10/site-packages/starlette/routing.py", line 74, in app
    response = await func(request)
  File "/home/thrymr/.local/lib/python3.10/site-packages/fastapi/routing.py", line 317, in app
    raise FastAPIError(
fastapi.exceptions.FastAPIError: No response object was returned. There's a high chance that the application code is raising an exception and a dependency with yield has a block with a bare except, or a block with except Exception, and is not raising the exception again. Read more about it in the docs: https://fastapi.tiangolo.com/tutorial/dependencies/dependencies-with-yield/#dependencies-with-yield-and-except
2024-04-19 13:09:35,196-ERROR-Exception in ASGI application
Traceback (most recent call last):
  File "/home/thrymr/.local/lib/python3.10/site-packages/uvicorn/protocols/http/httptools_impl.py", line 376, in run_asgi
    result = await app(self.scope, self.receive, self.send)
  File "/home/thrymr/.local/lib/python3.10/site-packages/uvicorn/middleware/proxy_headers.py", line 75, in __call__
    return await self.app(scope, receive, send)
  File "/home/thrymr/.local/lib/python3.10/site-packages/fastapi/applications.py", line 1054, in __call__
    await super().__call__(scope, receive, send)
  File "/home/thrymr/.local/lib/python3.10/site-packages/starlette/applications.py", line 123, in __call__
    await self.middleware_stack(scope, receive, send)
  File "/home/thrymr/.local/lib/python3.10/site-packages/starlette/middleware/errors.py", line 186, in __call__
    raise exc
  File "/home/thrymr/.local/lib/python3.10/site-packages/starlette/middleware/errors.py", line 164, in __call__
    await self.app(scope, receive, _send)
  File "/home/thrymr/.local/lib/python3.10/site-packages/starlette/middleware/cors.py", line 91, in __call__
    await self.simple_response(scope, receive, send, request_headers=headers)
  File "/home/thrymr/.local/lib/python3.10/site-packages/starlette/middleware/cors.py", line 146, in simple_response
    await self.app(scope, receive, send)
  File "/home/thrymr/.local/lib/python3.10/site-packages/starlette/middleware/exceptions.py", line 62, in __call__
    await wrap_app_handling_exceptions(self.app, conn)(scope, receive, send)
  File "/home/thrymr/.local/lib/python3.10/site-packages/starlette/_exception_handler.py", line 64, in wrapped_app
    raise exc
  File "/home/thrymr/.local/lib/python3.10/site-packages/starlette/_exception_handler.py", line 53, in wrapped_app
    await app(scope, receive, sender)
  File "/home/thrymr/.local/lib/python3.10/site-packages/starlette/routing.py", line 758, in __call__
    await self.middleware_stack(scope, receive, send)
  File "/home/thrymr/.local/lib/python3.10/site-packages/starlette/routing.py", line 778, in app
    await route.handle(scope, receive, send)
  File "/home/thrymr/.local/lib/python3.10/site-packages/starlette/routing.py", line 299, in handle
    await self.app(scope, receive, send)
  File "/home/thrymr/.local/lib/python3.10/site-packages/starlette/routing.py", line 79, in app
    await wrap_app_handling_exceptions(app, request)(scope, receive, send)
  File "/home/thrymr/.local/lib/python3.10/site-packages/starlette/_exception_handler.py", line 64, in wrapped_app
    raise exc
  File "/home/thrymr/.local/lib/python3.10/site-packages/starlette/_exception_handler.py", line 53, in wrapped_app
    await app(scope, receive, sender)
  File "/home/thrymr/.local/lib/python3.10/site-packages/starlette/routing.py", line 74, in app
    response = await func(request)
  File "/home/thrymr/.local/lib/python3.10/site-packages/fastapi/routing.py", line 317, in app
    raise FastAPIError(
fastapi.exceptions.FastAPIError: No response object was returned. There's a high chance that the application code is raising an exception and a dependency with yield has a block with a bare except, or a block with except Exception, and is not raising the exception again. Read more about it in the docs: https://fastapi.tiangolo.com/tutorial/dependencies/dependencies-with-yield/#dependencies-with-yield-and-except
2024-04-19 13:14:28,980-INFO-Shutting down
2024-04-19 13:14:29,081-INFO-Waiting for application shutdown.
2024-04-19 13:14:29,083-INFO-Application shutdown complete.
2024-04-19 13:14:29,083-INFO-Finished server process [74290]
2024-04-19 13:14:30,188-INFO-Started server process [74678]
2024-04-19 13:14:30,188-INFO-Waiting for application startup.
2024-04-19 13:14:30,189-INFO-Application startup complete.
2024-04-19 13:14:32,094-INFO-Shutting down
2024-04-19 13:14:32,195-INFO-Waiting for application shutdown.
2024-04-19 13:14:32,195-INFO-Application shutdown complete.
2024-04-19 13:14:32,196-INFO-Finished server process [74678]
2024-04-19 13:14:41,095-INFO-Started server process [74693]
2024-04-19 13:14:41,095-INFO-Waiting for application startup.
2024-04-19 13:14:41,096-INFO-Application startup complete.
2024-04-19 13:15:24,450-ERROR-Exception in ASGI application
Traceback (most recent call last):
  File "/home/thrymr/.local/lib/python3.10/site-packages/uvicorn/protocols/http/httptools_impl.py", line 376, in run_asgi
    result = await app(self.scope, self.receive, self.send)
  File "/home/thrymr/.local/lib/python3.10/site-packages/uvicorn/middleware/proxy_headers.py", line 75, in __call__
    return await self.app(scope, receive, send)
  File "/home/thrymr/.local/lib/python3.10/site-packages/fastapi/applications.py", line 1054, in __call__
    await super().__call__(scope, receive, send)
  File "/home/thrymr/.local/lib/python3.10/site-packages/starlette/applications.py", line 123, in __call__
    await self.middleware_stack(scope, receive, send)
  File "/home/thrymr/.local/lib/python3.10/site-packages/starlette/middleware/errors.py", line 186, in __call__
    raise exc
  File "/home/thrymr/.local/lib/python3.10/site-packages/starlette/middleware/errors.py", line 164, in __call__
    await self.app(scope, receive, _send)
  File "/home/thrymr/.local/lib/python3.10/site-packages/starlette/middleware/cors.py", line 91, in __call__
    await self.simple_response(scope, receive, send, request_headers=headers)
  File "/home/thrymr/.local/lib/python3.10/site-packages/starlette/middleware/cors.py", line 146, in simple_response
    await self.app(scope, receive, send)
  File "/home/thrymr/.local/lib/python3.10/site-packages/starlette/middleware/exceptions.py", line 62, in __call__
    await wrap_app_handling_exceptions(self.app, conn)(scope, receive, send)
  File "/home/thrymr/.local/lib/python3.10/site-packages/starlette/_exception_handler.py", line 64, in wrapped_app
    raise exc
  File "/home/thrymr/.local/lib/python3.10/site-packages/starlette/_exception_handler.py", line 53, in wrapped_app
    await app(scope, receive, sender)
  File "/home/thrymr/.local/lib/python3.10/site-packages/starlette/routing.py", line 758, in __call__
    await self.middleware_stack(scope, receive, send)
  File "/home/thrymr/.local/lib/python3.10/site-packages/starlette/routing.py", line 778, in app
    await route.handle(scope, receive, send)
  File "/home/thrymr/.local/lib/python3.10/site-packages/starlette/routing.py", line 299, in handle
    await self.app(scope, receive, send)
  File "/home/thrymr/.local/lib/python3.10/site-packages/starlette/routing.py", line 79, in app
    await wrap_app_handling_exceptions(app, request)(scope, receive, send)
  File "/home/thrymr/.local/lib/python3.10/site-packages/starlette/_exception_handler.py", line 64, in wrapped_app
    raise exc
  File "/home/thrymr/.local/lib/python3.10/site-packages/starlette/_exception_handler.py", line 53, in wrapped_app
    await app(scope, receive, sender)
  File "/home/thrymr/.local/lib/python3.10/site-packages/starlette/routing.py", line 74, in app
    response = await func(request)
  File "/home/thrymr/.local/lib/python3.10/site-packages/fastapi/routing.py", line 317, in app
    raise FastAPIError(
fastapi.exceptions.FastAPIError: No response object was returned. There's a high chance that the application code is raising an exception and a dependency with yield has a block with a bare except, or a block with except Exception, and is not raising the exception again. Read more about it in the docs: https://fastapi.tiangolo.com/tutorial/dependencies/dependencies-with-yield/#dependencies-with-yield-and-except
2024-04-19 13:17:11,577-INFO-Shutting down
2024-04-19 13:17:11,678-INFO-Waiting for application shutdown.
2024-04-19 13:17:11,678-INFO-Application shutdown complete.
2024-04-19 13:17:11,678-INFO-Finished server process [74693]
2024-04-19 13:17:12,816-INFO-Started server process [74850]
2024-04-19 13:17:12,817-INFO-Waiting for application startup.
2024-04-19 13:17:12,817-INFO-Application startup complete.
2024-04-19 13:18:04,632-ERROR-Exception in ASGI application
Traceback (most recent call last):
  File "/home/thrymr/.local/lib/python3.10/site-packages/uvicorn/protocols/http/httptools_impl.py", line 376, in run_asgi
    result = await app(self.scope, self.receive, self.send)
  File "/home/thrymr/.local/lib/python3.10/site-packages/uvicorn/middleware/proxy_headers.py", line 75, in __call__
    return await self.app(scope, receive, send)
  File "/home/thrymr/.local/lib/python3.10/site-packages/fastapi/applications.py", line 1054, in __call__
    await super().__call__(scope, receive, send)
  File "/home/thrymr/.local/lib/python3.10/site-packages/starlette/applications.py", line 123, in __call__
    await self.middleware_stack(scope, receive, send)
  File "/home/thrymr/.local/lib/python3.10/site-packages/starlette/middleware/errors.py", line 186, in __call__
    raise exc
  File "/home/thrymr/.local/lib/python3.10/site-packages/starlette/middleware/errors.py", line 164, in __call__
    await self.app(scope, receive, _send)
  File "/home/thrymr/.local/lib/python3.10/site-packages/starlette/middleware/cors.py", line 91, in __call__
    await self.simple_response(scope, receive, send, request_headers=headers)
  File "/home/thrymr/.local/lib/python3.10/site-packages/starlette/middleware/cors.py", line 146, in simple_response
    await self.app(scope, receive, send)
  File "/home/thrymr/.local/lib/python3.10/site-packages/starlette/middleware/exceptions.py", line 62, in __call__
    await wrap_app_handling_exceptions(self.app, conn)(scope, receive, send)
  File "/home/thrymr/.local/lib/python3.10/site-packages/starlette/_exception_handler.py", line 64, in wrapped_app
    raise exc
  File "/home/thrymr/.local/lib/python3.10/site-packages/starlette/_exception_handler.py", line 53, in wrapped_app
    await app(scope, receive, sender)
  File "/home/thrymr/.local/lib/python3.10/site-packages/starlette/routing.py", line 758, in __call__
    await self.middleware_stack(scope, receive, send)
  File "/home/thrymr/.local/lib/python3.10/site-packages/starlette/routing.py", line 778, in app
    await route.handle(scope, receive, send)
  File "/home/thrymr/.local/lib/python3.10/site-packages/starlette/routing.py", line 299, in handle
    await self.app(scope, receive, send)
  File "/home/thrymr/.local/lib/python3.10/site-packages/starlette/routing.py", line 79, in app
    await wrap_app_handling_exceptions(app, request)(scope, receive, send)
  File "/home/thrymr/.local/lib/python3.10/site-packages/starlette/_exception_handler.py", line 64, in wrapped_app
    raise exc
  File "/home/thrymr/.local/lib/python3.10/site-packages/starlette/_exception_handler.py", line 53, in wrapped_app
    await app(scope, receive, sender)
  File "/home/thrymr/.local/lib/python3.10/site-packages/starlette/routing.py", line 74, in app
    response = await func(request)
  File "/home/thrymr/.local/lib/python3.10/site-packages/fastapi/routing.py", line 317, in app
    raise FastAPIError(
fastapi.exceptions.FastAPIError: No response object was returned. There's a high chance that the application code is raising an exception and a dependency with yield has a block with a bare except, or a block with except Exception, and is not raising the exception again. Read more about it in the docs: https://fastapi.tiangolo.com/tutorial/dependencies/dependencies-with-yield/#dependencies-with-yield-and-except
2024-04-19 13:18:15,631-ERROR-Exception in ASGI application
Traceback (most recent call last):
  File "/home/thrymr/.local/lib/python3.10/site-packages/uvicorn/protocols/http/httptools_impl.py", line 376, in run_asgi
    result = await app(self.scope, self.receive, self.send)
  File "/home/thrymr/.local/lib/python3.10/site-packages/uvicorn/middleware/proxy_headers.py", line 75, in __call__
    return await self.app(scope, receive, send)
  File "/home/thrymr/.local/lib/python3.10/site-packages/fastapi/applications.py", line 1054, in __call__
    await super().__call__(scope, receive, send)
  File "/home/thrymr/.local/lib/python3.10/site-packages/starlette/applications.py", line 123, in __call__
    await self.middleware_stack(scope, receive, send)
  File "/home/thrymr/.local/lib/python3.10/site-packages/starlette/middleware/errors.py", line 186, in __call__
    raise exc
  File "/home/thrymr/.local/lib/python3.10/site-packages/starlette/middleware/errors.py", line 164, in __call__
    await self.app(scope, receive, _send)
  File "/home/thrymr/.local/lib/python3.10/site-packages/starlette/middleware/cors.py", line 91, in __call__
    await self.simple_response(scope, receive, send, request_headers=headers)
  File "/home/thrymr/.local/lib/python3.10/site-packages/starlette/middleware/cors.py", line 146, in simple_response
    await self.app(scope, receive, send)
  File "/home/thrymr/.local/lib/python3.10/site-packages/starlette/middleware/exceptions.py", line 62, in __call__
    await wrap_app_handling_exceptions(self.app, conn)(scope, receive, send)
  File "/home/thrymr/.local/lib/python3.10/site-packages/starlette/_exception_handler.py", line 64, in wrapped_app
    raise exc
  File "/home/thrymr/.local/lib/python3.10/site-packages/starlette/_exception_handler.py", line 53, in wrapped_app
    await app(scope, receive, sender)
  File "/home/thrymr/.local/lib/python3.10/site-packages/starlette/routing.py", line 758, in __call__
    await self.middleware_stack(scope, receive, send)
  File "/home/thrymr/.local/lib/python3.10/site-packages/starlette/routing.py", line 778, in app
    await route.handle(scope, receive, send)
  File "/home/thrymr/.local/lib/python3.10/site-packages/starlette/routing.py", line 299, in handle
    await self.app(scope, receive, send)
  File "/home/thrymr/.local/lib/python3.10/site-packages/starlette/routing.py", line 79, in app
    await wrap_app_handling_exceptions(app, request)(scope, receive, send)
  File "/home/thrymr/.local/lib/python3.10/site-packages/starlette/_exception_handler.py", line 64, in wrapped_app
    raise exc
  File "/home/thrymr/.local/lib/python3.10/site-packages/starlette/_exception_handler.py", line 53, in wrapped_app
    await app(scope, receive, sender)
  File "/home/thrymr/.local/lib/python3.10/site-packages/starlette/routing.py", line 74, in app
    response = await func(request)
  File "/home/thrymr/.local/lib/python3.10/site-packages/fastapi/routing.py", line 317, in app
    raise FastAPIError(
fastapi.exceptions.FastAPIError: No response object was returned. There's a high chance that the application code is raising an exception and a dependency with yield has a block with a bare except, or a block with except Exception, and is not raising the exception again. Read more about it in the docs: https://fastapi.tiangolo.com/tutorial/dependencies/dependencies-with-yield/#dependencies-with-yield-and-except
2024-04-19 13:18:53,882-INFO-Shutting down
2024-04-19 13:18:53,983-INFO-Waiting for application shutdown.
2024-04-19 13:18:53,983-INFO-Application shutdown complete.
2024-04-19 13:18:53,983-INFO-Finished server process [74850]
2024-04-19 13:18:55,083-INFO-Started server process [74984]
2024-04-19 13:18:55,083-INFO-Waiting for application startup.
2024-04-19 13:18:55,083-INFO-Application startup complete.
2024-04-19 13:18:57,950-ERROR-Exception in ASGI application
Traceback (most recent call last):
  File "/home/thrymr/.local/lib/python3.10/site-packages/uvicorn/protocols/http/httptools_impl.py", line 376, in run_asgi
    result = await app(self.scope, self.receive, self.send)
  File "/home/thrymr/.local/lib/python3.10/site-packages/uvicorn/middleware/proxy_headers.py", line 75, in __call__
    return await self.app(scope, receive, send)
  File "/home/thrymr/.local/lib/python3.10/site-packages/fastapi/applications.py", line 1054, in __call__
    await super().__call__(scope, receive, send)
  File "/home/thrymr/.local/lib/python3.10/site-packages/starlette/applications.py", line 123, in __call__
    await self.middleware_stack(scope, receive, send)
  File "/home/thrymr/.local/lib/python3.10/site-packages/starlette/middleware/errors.py", line 186, in __call__
    raise exc
  File "/home/thrymr/.local/lib/python3.10/site-packages/starlette/middleware/errors.py", line 164, in __call__
    await self.app(scope, receive, _send)
  File "/home/thrymr/.local/lib/python3.10/site-packages/starlette/middleware/cors.py", line 91, in __call__
    await self.simple_response(scope, receive, send, request_headers=headers)
  File "/home/thrymr/.local/lib/python3.10/site-packages/starlette/middleware/cors.py", line 146, in simple_response
    await self.app(scope, receive, send)
  File "/home/thrymr/.local/lib/python3.10/site-packages/starlette/middleware/exceptions.py", line 62, in __call__
    await wrap_app_handling_exceptions(self.app, conn)(scope, receive, send)
  File "/home/thrymr/.local/lib/python3.10/site-packages/starlette/_exception_handler.py", line 64, in wrapped_app
    raise exc
  File "/home/thrymr/.local/lib/python3.10/site-packages/starlette/_exception_handler.py", line 53, in wrapped_app
    await app(scope, receive, sender)
  File "/home/thrymr/.local/lib/python3.10/site-packages/starlette/routing.py", line 758, in __call__
    await self.middleware_stack(scope, receive, send)
  File "/home/thrymr/.local/lib/python3.10/site-packages/starlette/routing.py", line 778, in app
    await route.handle(scope, receive, send)
  File "/home/thrymr/.local/lib/python3.10/site-packages/starlette/routing.py", line 299, in handle
    await self.app(scope, receive, send)
  File "/home/thrymr/.local/lib/python3.10/site-packages/starlette/routing.py", line 79, in app
    await wrap_app_handling_exceptions(app, request)(scope, receive, send)
  File "/home/thrymr/.local/lib/python3.10/site-packages/starlette/_exception_handler.py", line 64, in wrapped_app
    raise exc
  File "/home/thrymr/.local/lib/python3.10/site-packages/starlette/_exception_handler.py", line 53, in wrapped_app
    await app(scope, receive, sender)
  File "/home/thrymr/.local/lib/python3.10/site-packages/starlette/routing.py", line 74, in app
    response = await func(request)
  File "/home/thrymr/.local/lib/python3.10/site-packages/fastapi/routing.py", line 317, in app
    raise FastAPIError(
fastapi.exceptions.FastAPIError: No response object was returned. There's a high chance that the application code is raising an exception and a dependency with yield has a block with a bare except, or a block with except Exception, and is not raising the exception again. Read more about it in the docs: https://fastapi.tiangolo.com/tutorial/dependencies/dependencies-with-yield/#dependencies-with-yield-and-except
2024-04-19 13:19:22,770-INFO-Shutting down
2024-04-19 13:19:22,871-INFO-Waiting for application shutdown.
2024-04-19 13:19:22,872-INFO-Application shutdown complete.
2024-04-19 13:19:22,873-INFO-Finished server process [74984]
2024-04-19 13:19:24,023-INFO-Started server process [75412]
2024-04-19 13:19:24,023-INFO-Waiting for application startup.
2024-04-19 13:19:24,024-INFO-Application startup complete.
2024-04-19 13:19:25,809-ERROR-Exception in ASGI application
Traceback (most recent call last):
  File "/home/thrymr/.local/lib/python3.10/site-packages/uvicorn/protocols/http/httptools_impl.py", line 376, in run_asgi
    result = await app(self.scope, self.receive, self.send)
  File "/home/thrymr/.local/lib/python3.10/site-packages/uvicorn/middleware/proxy_headers.py", line 75, in __call__
    return await self.app(scope, receive, send)
  File "/home/thrymr/.local/lib/python3.10/site-packages/fastapi/applications.py", line 1054, in __call__
    await super().__call__(scope, receive, send)
  File "/home/thrymr/.local/lib/python3.10/site-packages/starlette/applications.py", line 123, in __call__
    await self.middleware_stack(scope, receive, send)
  File "/home/thrymr/.local/lib/python3.10/site-packages/starlette/middleware/errors.py", line 186, in __call__
    raise exc
  File "/home/thrymr/.local/lib/python3.10/site-packages/starlette/middleware/errors.py", line 164, in __call__
    await self.app(scope, receive, _send)
  File "/home/thrymr/.local/lib/python3.10/site-packages/starlette/middleware/cors.py", line 91, in __call__
    await self.simple_response(scope, receive, send, request_headers=headers)
  File "/home/thrymr/.local/lib/python3.10/site-packages/starlette/middleware/cors.py", line 146, in simple_response
    await self.app(scope, receive, send)
  File "/home/thrymr/.local/lib/python3.10/site-packages/starlette/middleware/exceptions.py", line 62, in __call__
    await wrap_app_handling_exceptions(self.app, conn)(scope, receive, send)
  File "/home/thrymr/.local/lib/python3.10/site-packages/starlette/_exception_handler.py", line 64, in wrapped_app
    raise exc
  File "/home/thrymr/.local/lib/python3.10/site-packages/starlette/_exception_handler.py", line 53, in wrapped_app
    await app(scope, receive, sender)
  File "/home/thrymr/.local/lib/python3.10/site-packages/starlette/routing.py", line 758, in __call__
    await self.middleware_stack(scope, receive, send)
  File "/home/thrymr/.local/lib/python3.10/site-packages/starlette/routing.py", line 778, in app
    await route.handle(scope, receive, send)
  File "/home/thrymr/.local/lib/python3.10/site-packages/starlette/routing.py", line 299, in handle
    await self.app(scope, receive, send)
  File "/home/thrymr/.local/lib/python3.10/site-packages/starlette/routing.py", line 79, in app
    await wrap_app_handling_exceptions(app, request)(scope, receive, send)
  File "/home/thrymr/.local/lib/python3.10/site-packages/starlette/_exception_handler.py", line 64, in wrapped_app
    raise exc
  File "/home/thrymr/.local/lib/python3.10/site-packages/starlette/_exception_handler.py", line 53, in wrapped_app
    await app(scope, receive, sender)
  File "/home/thrymr/.local/lib/python3.10/site-packages/starlette/routing.py", line 74, in app
    response = await func(request)
  File "/home/thrymr/.local/lib/python3.10/site-packages/fastapi/routing.py", line 317, in app
    raise FastAPIError(
fastapi.exceptions.FastAPIError: No response object was returned. There's a high chance that the application code is raising an exception and a dependency with yield has a block with a bare except, or a block with except Exception, and is not raising the exception again. Read more about it in the docs: https://fastapi.tiangolo.com/tutorial/dependencies/dependencies-with-yield/#dependencies-with-yield-and-except
2024-04-19 13:20:25,686-INFO-Shutting down
2024-04-19 13:20:25,786-INFO-Waiting for application shutdown.
2024-04-19 13:20:25,787-INFO-Application shutdown complete.
2024-04-19 13:20:25,788-INFO-Finished server process [75412]
2024-04-19 13:20:26,927-INFO-Started server process [75487]
2024-04-19 13:20:26,927-INFO-Waiting for application startup.
2024-04-19 13:20:26,928-INFO-Application startup complete.
2024-04-19 13:21:12,852-INFO-Shutting down
2024-04-19 13:21:12,952-INFO-Waiting for application shutdown.
2024-04-19 13:21:12,953-INFO-Application shutdown complete.
2024-04-19 13:21:12,953-INFO-Finished server process [75487]
2024-04-19 13:21:14,113-INFO-Started server process [75539]
2024-04-19 13:21:14,114-INFO-Waiting for application startup.
2024-04-19 13:21:14,114-INFO-Application startup complete.
2024-04-19 13:21:16,518-ERROR-Exception in ASGI application
Traceback (most recent call last):
  File "/home/thrymr/.local/lib/python3.10/site-packages/uvicorn/protocols/http/httptools_impl.py", line 376, in run_asgi
    result = await app(self.scope, self.receive, self.send)
  File "/home/thrymr/.local/lib/python3.10/site-packages/uvicorn/middleware/proxy_headers.py", line 75, in __call__
    return await self.app(scope, receive, send)
  File "/home/thrymr/.local/lib/python3.10/site-packages/fastapi/applications.py", line 1054, in __call__
    await super().__call__(scope, receive, send)
  File "/home/thrymr/.local/lib/python3.10/site-packages/starlette/applications.py", line 123, in __call__
    await self.middleware_stack(scope, receive, send)
  File "/home/thrymr/.local/lib/python3.10/site-packages/starlette/middleware/errors.py", line 186, in __call__
    raise exc
  File "/home/thrymr/.local/lib/python3.10/site-packages/starlette/middleware/errors.py", line 164, in __call__
    await self.app(scope, receive, _send)
  File "/home/thrymr/.local/lib/python3.10/site-packages/starlette/middleware/cors.py", line 91, in __call__
    await self.simple_response(scope, receive, send, request_headers=headers)
  File "/home/thrymr/.local/lib/python3.10/site-packages/starlette/middleware/cors.py", line 146, in simple_response
    await self.app(scope, receive, send)
  File "/home/thrymr/.local/lib/python3.10/site-packages/starlette/middleware/exceptions.py", line 62, in __call__
    await wrap_app_handling_exceptions(self.app, conn)(scope, receive, send)
  File "/home/thrymr/.local/lib/python3.10/site-packages/starlette/_exception_handler.py", line 64, in wrapped_app
    raise exc
  File "/home/thrymr/.local/lib/python3.10/site-packages/starlette/_exception_handler.py", line 53, in wrapped_app
    await app(scope, receive, sender)
  File "/home/thrymr/.local/lib/python3.10/site-packages/starlette/routing.py", line 758, in __call__
    await self.middleware_stack(scope, receive, send)
  File "/home/thrymr/.local/lib/python3.10/site-packages/starlette/routing.py", line 778, in app
    await route.handle(scope, receive, send)
  File "/home/thrymr/.local/lib/python3.10/site-packages/starlette/routing.py", line 299, in handle
    await self.app(scope, receive, send)
  File "/home/thrymr/.local/lib/python3.10/site-packages/starlette/routing.py", line 79, in app
    await wrap_app_handling_exceptions(app, request)(scope, receive, send)
  File "/home/thrymr/.local/lib/python3.10/site-packages/starlette/_exception_handler.py", line 64, in wrapped_app
    raise exc
  File "/home/thrymr/.local/lib/python3.10/site-packages/starlette/_exception_handler.py", line 53, in wrapped_app
    await app(scope, receive, sender)
  File "/home/thrymr/.local/lib/python3.10/site-packages/starlette/routing.py", line 74, in app
    response = await func(request)
  File "/home/thrymr/.local/lib/python3.10/site-packages/fastapi/routing.py", line 317, in app
    raise FastAPIError(
fastapi.exceptions.FastAPIError: No response object was returned. There's a high chance that the application code is raising an exception and a dependency with yield has a block with a bare except, or a block with except Exception, and is not raising the exception again. Read more about it in the docs: https://fastapi.tiangolo.com/tutorial/dependencies/dependencies-with-yield/#dependencies-with-yield-and-except
2024-04-19 13:21:39,381-INFO-Shutting down
2024-04-19 13:21:39,483-INFO-Waiting for application shutdown.
2024-04-19 13:21:39,484-INFO-Application shutdown complete.
2024-04-19 13:21:39,485-INFO-Finished server process [75539]
2024-04-19 13:21:40,706-INFO-Started server process [75578]
2024-04-19 13:21:40,706-INFO-Waiting for application startup.
2024-04-19 13:21:40,706-INFO-Application startup complete.
2024-04-19 13:21:46,973-ERROR-Exception in ASGI application
Traceback (most recent call last):
  File "/home/thrymr/.local/lib/python3.10/site-packages/uvicorn/protocols/http/httptools_impl.py", line 376, in run_asgi
    result = await app(self.scope, self.receive, self.send)
  File "/home/thrymr/.local/lib/python3.10/site-packages/uvicorn/middleware/proxy_headers.py", line 75, in __call__
    return await self.app(scope, receive, send)
  File "/home/thrymr/.local/lib/python3.10/site-packages/fastapi/applications.py", line 1054, in __call__
    await super().__call__(scope, receive, send)
  File "/home/thrymr/.local/lib/python3.10/site-packages/starlette/applications.py", line 123, in __call__
    await self.middleware_stack(scope, receive, send)
  File "/home/thrymr/.local/lib/python3.10/site-packages/starlette/middleware/errors.py", line 186, in __call__
    raise exc
  File "/home/thrymr/.local/lib/python3.10/site-packages/starlette/middleware/errors.py", line 164, in __call__
    await self.app(scope, receive, _send)
  File "/home/thrymr/.local/lib/python3.10/site-packages/starlette/middleware/cors.py", line 91, in __call__
    await self.simple_response(scope, receive, send, request_headers=headers)
  File "/home/thrymr/.local/lib/python3.10/site-packages/starlette/middleware/cors.py", line 146, in simple_response
    await self.app(scope, receive, send)
  File "/home/thrymr/.local/lib/python3.10/site-packages/starlette/middleware/exceptions.py", line 62, in __call__
    await wrap_app_handling_exceptions(self.app, conn)(scope, receive, send)
  File "/home/thrymr/.local/lib/python3.10/site-packages/starlette/_exception_handler.py", line 64, in wrapped_app
    raise exc
  File "/home/thrymr/.local/lib/python3.10/site-packages/starlette/_exception_handler.py", line 53, in wrapped_app
    await app(scope, receive, sender)
  File "/home/thrymr/.local/lib/python3.10/site-packages/starlette/routing.py", line 758, in __call__
    await self.middleware_stack(scope, receive, send)
  File "/home/thrymr/.local/lib/python3.10/site-packages/starlette/routing.py", line 778, in app
    await route.handle(scope, receive, send)
  File "/home/thrymr/.local/lib/python3.10/site-packages/starlette/routing.py", line 299, in handle
    await self.app(scope, receive, send)
  File "/home/thrymr/.local/lib/python3.10/site-packages/starlette/routing.py", line 79, in app
    await wrap_app_handling_exceptions(app, request)(scope, receive, send)
  File "/home/thrymr/.local/lib/python3.10/site-packages/starlette/_exception_handler.py", line 64, in wrapped_app
    raise exc
  File "/home/thrymr/.local/lib/python3.10/site-packages/starlette/_exception_handler.py", line 53, in wrapped_app
    await app(scope, receive, sender)
  File "/home/thrymr/.local/lib/python3.10/site-packages/starlette/routing.py", line 74, in app
    response = await func(request)
  File "/home/thrymr/.local/lib/python3.10/site-packages/fastapi/routing.py", line 317, in app
    raise FastAPIError(
fastapi.exceptions.FastAPIError: No response object was returned. There's a high chance that the application code is raising an exception and a dependency with yield has a block with a bare except, or a block with except Exception, and is not raising the exception again. Read more about it in the docs: https://fastapi.tiangolo.com/tutorial/dependencies/dependencies-with-yield/#dependencies-with-yield-and-except
2024-04-19 13:23:03,623-INFO-Shutting down
2024-04-19 13:23:03,724-INFO-Waiting for application shutdown.
2024-04-19 13:23:03,724-INFO-Application shutdown complete.
2024-04-19 13:23:03,725-INFO-Finished server process [75578]
2024-04-19 13:23:04,844-INFO-Started server process [75667]
2024-04-19 13:23:04,844-INFO-Waiting for application startup.
2024-04-19 13:23:04,844-INFO-Application startup complete.
2024-04-19 13:23:08,627-ERROR-Exception in ASGI application
Traceback (most recent call last):
  File "/home/thrymr/.local/lib/python3.10/site-packages/uvicorn/protocols/http/httptools_impl.py", line 376, in run_asgi
    result = await app(self.scope, self.receive, self.send)
  File "/home/thrymr/.local/lib/python3.10/site-packages/uvicorn/middleware/proxy_headers.py", line 75, in __call__
    return await self.app(scope, receive, send)
  File "/home/thrymr/.local/lib/python3.10/site-packages/fastapi/applications.py", line 1054, in __call__
    await super().__call__(scope, receive, send)
  File "/home/thrymr/.local/lib/python3.10/site-packages/starlette/applications.py", line 123, in __call__
    await self.middleware_stack(scope, receive, send)
  File "/home/thrymr/.local/lib/python3.10/site-packages/starlette/middleware/errors.py", line 186, in __call__
    raise exc
  File "/home/thrymr/.local/lib/python3.10/site-packages/starlette/middleware/errors.py", line 164, in __call__
    await self.app(scope, receive, _send)
  File "/home/thrymr/.local/lib/python3.10/site-packages/starlette/middleware/cors.py", line 91, in __call__
    await self.simple_response(scope, receive, send, request_headers=headers)
  File "/home/thrymr/.local/lib/python3.10/site-packages/starlette/middleware/cors.py", line 146, in simple_response
    await self.app(scope, receive, send)
  File "/home/thrymr/.local/lib/python3.10/site-packages/starlette/middleware/exceptions.py", line 62, in __call__
    await wrap_app_handling_exceptions(self.app, conn)(scope, receive, send)
  File "/home/thrymr/.local/lib/python3.10/site-packages/starlette/_exception_handler.py", line 64, in wrapped_app
    raise exc
  File "/home/thrymr/.local/lib/python3.10/site-packages/starlette/_exception_handler.py", line 53, in wrapped_app
    await app(scope, receive, sender)
  File "/home/thrymr/.local/lib/python3.10/site-packages/starlette/routing.py", line 758, in __call__
    await self.middleware_stack(scope, receive, send)
  File "/home/thrymr/.local/lib/python3.10/site-packages/starlette/routing.py", line 778, in app
    await route.handle(scope, receive, send)
  File "/home/thrymr/.local/lib/python3.10/site-packages/starlette/routing.py", line 299, in handle
    await self.app(scope, receive, send)
  File "/home/thrymr/.local/lib/python3.10/site-packages/starlette/routing.py", line 79, in app
    await wrap_app_handling_exceptions(app, request)(scope, receive, send)
  File "/home/thrymr/.local/lib/python3.10/site-packages/starlette/_exception_handler.py", line 64, in wrapped_app
    raise exc
  File "/home/thrymr/.local/lib/python3.10/site-packages/starlette/_exception_handler.py", line 53, in wrapped_app
    await app(scope, receive, sender)
  File "/home/thrymr/.local/lib/python3.10/site-packages/starlette/routing.py", line 74, in app
    response = await func(request)
  File "/home/thrymr/.local/lib/python3.10/site-packages/fastapi/routing.py", line 317, in app
    raise FastAPIError(
fastapi.exceptions.FastAPIError: No response object was returned. There's a high chance that the application code is raising an exception and a dependency with yield has a block with a bare except, or a block with except Exception, and is not raising the exception again. Read more about it in the docs: https://fastapi.tiangolo.com/tutorial/dependencies/dependencies-with-yield/#dependencies-with-yield-and-except
2024-04-19 13:23:56,777-INFO-Shutting down
2024-04-19 13:23:56,877-INFO-Waiting for application shutdown.
2024-04-19 13:23:56,878-INFO-Application shutdown complete.
2024-04-19 13:23:56,878-INFO-Finished server process [75667]
2024-04-19 13:23:58,058-INFO-Started server process [75730]
2024-04-19 13:23:58,058-INFO-Waiting for application startup.
2024-04-19 13:23:58,058-INFO-Application startup complete.
2024-04-19 13:24:00,233-ERROR-Exception in ASGI application
Traceback (most recent call last):
  File "/home/thrymr/.local/lib/python3.10/site-packages/uvicorn/protocols/http/httptools_impl.py", line 376, in run_asgi
    result = await app(self.scope, self.receive, self.send)
  File "/home/thrymr/.local/lib/python3.10/site-packages/uvicorn/middleware/proxy_headers.py", line 75, in __call__
    return await self.app(scope, receive, send)
  File "/home/thrymr/.local/lib/python3.10/site-packages/fastapi/applications.py", line 1054, in __call__
    await super().__call__(scope, receive, send)
  File "/home/thrymr/.local/lib/python3.10/site-packages/starlette/applications.py", line 123, in __call__
    await self.middleware_stack(scope, receive, send)
  File "/home/thrymr/.local/lib/python3.10/site-packages/starlette/middleware/errors.py", line 186, in __call__
    raise exc
  File "/home/thrymr/.local/lib/python3.10/site-packages/starlette/middleware/errors.py", line 164, in __call__
    await self.app(scope, receive, _send)
  File "/home/thrymr/.local/lib/python3.10/site-packages/starlette/middleware/cors.py", line 91, in __call__
    await self.simple_response(scope, receive, send, request_headers=headers)
  File "/home/thrymr/.local/lib/python3.10/site-packages/starlette/middleware/cors.py", line 146, in simple_response
    await self.app(scope, receive, send)
  File "/home/thrymr/.local/lib/python3.10/site-packages/starlette/middleware/exceptions.py", line 62, in __call__
    await wrap_app_handling_exceptions(self.app, conn)(scope, receive, send)
  File "/home/thrymr/.local/lib/python3.10/site-packages/starlette/_exception_handler.py", line 64, in wrapped_app
    raise exc
  File "/home/thrymr/.local/lib/python3.10/site-packages/starlette/_exception_handler.py", line 53, in wrapped_app
    await app(scope, receive, sender)
  File "/home/thrymr/.local/lib/python3.10/site-packages/starlette/routing.py", line 758, in __call__
    await self.middleware_stack(scope, receive, send)
  File "/home/thrymr/.local/lib/python3.10/site-packages/starlette/routing.py", line 778, in app
    await route.handle(scope, receive, send)
  File "/home/thrymr/.local/lib/python3.10/site-packages/starlette/routing.py", line 299, in handle
    await self.app(scope, receive, send)
  File "/home/thrymr/.local/lib/python3.10/site-packages/starlette/routing.py", line 79, in app
    await wrap_app_handling_exceptions(app, request)(scope, receive, send)
  File "/home/thrymr/.local/lib/python3.10/site-packages/starlette/_exception_handler.py", line 64, in wrapped_app
    raise exc
  File "/home/thrymr/.local/lib/python3.10/site-packages/starlette/_exception_handler.py", line 53, in wrapped_app
    await app(scope, receive, sender)
  File "/home/thrymr/.local/lib/python3.10/site-packages/starlette/routing.py", line 74, in app
    response = await func(request)
  File "/home/thrymr/.local/lib/python3.10/site-packages/fastapi/routing.py", line 317, in app
    raise FastAPIError(
fastapi.exceptions.FastAPIError: No response object was returned. There's a high chance that the application code is raising an exception and a dependency with yield has a block with a bare except, or a block with except Exception, and is not raising the exception again. Read more about it in the docs: https://fastapi.tiangolo.com/tutorial/dependencies/dependencies-with-yield/#dependencies-with-yield-and-except
2024-04-19 13:24:24,533-INFO-Shutting down
2024-04-19 13:24:24,633-INFO-Waiting for application shutdown.
2024-04-19 13:24:24,634-INFO-Application shutdown complete.
2024-04-19 13:24:24,635-INFO-Finished server process [75730]
2024-04-19 13:24:25,753-INFO-Started server process [75769]
2024-04-19 13:24:25,753-INFO-Waiting for application startup.
2024-04-19 13:24:25,753-INFO-Application startup complete.
2024-04-19 13:24:29,059-ERROR-Exception in ASGI application
Traceback (most recent call last):
  File "/home/thrymr/.local/lib/python3.10/site-packages/uvicorn/protocols/http/httptools_impl.py", line 376, in run_asgi
    result = await app(self.scope, self.receive, self.send)
  File "/home/thrymr/.local/lib/python3.10/site-packages/uvicorn/middleware/proxy_headers.py", line 75, in __call__
    return await self.app(scope, receive, send)
  File "/home/thrymr/.local/lib/python3.10/site-packages/fastapi/applications.py", line 1054, in __call__
    await super().__call__(scope, receive, send)
  File "/home/thrymr/.local/lib/python3.10/site-packages/starlette/applications.py", line 123, in __call__
    await self.middleware_stack(scope, receive, send)
  File "/home/thrymr/.local/lib/python3.10/site-packages/starlette/middleware/errors.py", line 186, in __call__
    raise exc
  File "/home/thrymr/.local/lib/python3.10/site-packages/starlette/middleware/errors.py", line 164, in __call__
    await self.app(scope, receive, _send)
  File "/home/thrymr/.local/lib/python3.10/site-packages/starlette/middleware/cors.py", line 91, in __call__
    await self.simple_response(scope, receive, send, request_headers=headers)
  File "/home/thrymr/.local/lib/python3.10/site-packages/starlette/middleware/cors.py", line 146, in simple_response
    await self.app(scope, receive, send)
  File "/home/thrymr/.local/lib/python3.10/site-packages/starlette/middleware/exceptions.py", line 62, in __call__
    await wrap_app_handling_exceptions(self.app, conn)(scope, receive, send)
  File "/home/thrymr/.local/lib/python3.10/site-packages/starlette/_exception_handler.py", line 64, in wrapped_app
    raise exc
  File "/home/thrymr/.local/lib/python3.10/site-packages/starlette/_exception_handler.py", line 53, in wrapped_app
    await app(scope, receive, sender)
  File "/home/thrymr/.local/lib/python3.10/site-packages/starlette/routing.py", line 758, in __call__
    await self.middleware_stack(scope, receive, send)
  File "/home/thrymr/.local/lib/python3.10/site-packages/starlette/routing.py", line 778, in app
    await route.handle(scope, receive, send)
  File "/home/thrymr/.local/lib/python3.10/site-packages/starlette/routing.py", line 299, in handle
    await self.app(scope, receive, send)
  File "/home/thrymr/.local/lib/python3.10/site-packages/starlette/routing.py", line 79, in app
    await wrap_app_handling_exceptions(app, request)(scope, receive, send)
  File "/home/thrymr/.local/lib/python3.10/site-packages/starlette/_exception_handler.py", line 64, in wrapped_app
    raise exc
  File "/home/thrymr/.local/lib/python3.10/site-packages/starlette/_exception_handler.py", line 53, in wrapped_app
    await app(scope, receive, sender)
  File "/home/thrymr/.local/lib/python3.10/site-packages/starlette/routing.py", line 74, in app
    response = await func(request)
  File "/home/thrymr/.local/lib/python3.10/site-packages/fastapi/routing.py", line 317, in app
    raise FastAPIError(
fastapi.exceptions.FastAPIError: No response object was returned. There's a high chance that the application code is raising an exception and a dependency with yield has a block with a bare except, or a block with except Exception, and is not raising the exception again. Read more about it in the docs: https://fastapi.tiangolo.com/tutorial/dependencies/dependencies-with-yield/#dependencies-with-yield-and-except
2024-04-19 13:24:59,947-INFO-Shutting down
2024-04-19 13:25:00,048-INFO-Waiting for application shutdown.
2024-04-19 13:25:00,048-INFO-Application shutdown complete.
2024-04-19 13:25:00,049-INFO-Finished server process [75769]
2024-04-19 13:25:01,214-INFO-Started server process [75814]
2024-04-19 13:25:01,214-INFO-Waiting for application startup.
2024-04-19 13:25:01,215-INFO-Application startup complete.
2024-04-19 13:25:03,584-ERROR-Exception in ASGI application
Traceback (most recent call last):
  File "/home/thrymr/.local/lib/python3.10/site-packages/uvicorn/protocols/http/httptools_impl.py", line 376, in run_asgi
    result = await app(self.scope, self.receive, self.send)
  File "/home/thrymr/.local/lib/python3.10/site-packages/uvicorn/middleware/proxy_headers.py", line 75, in __call__
    return await self.app(scope, receive, send)
  File "/home/thrymr/.local/lib/python3.10/site-packages/fastapi/applications.py", line 1054, in __call__
    await super().__call__(scope, receive, send)
  File "/home/thrymr/.local/lib/python3.10/site-packages/starlette/applications.py", line 123, in __call__
    await self.middleware_stack(scope, receive, send)
  File "/home/thrymr/.local/lib/python3.10/site-packages/starlette/middleware/errors.py", line 186, in __call__
    raise exc
  File "/home/thrymr/.local/lib/python3.10/site-packages/starlette/middleware/errors.py", line 164, in __call__
    await self.app(scope, receive, _send)
  File "/home/thrymr/.local/lib/python3.10/site-packages/starlette/middleware/cors.py", line 91, in __call__
    await self.simple_response(scope, receive, send, request_headers=headers)
  File "/home/thrymr/.local/lib/python3.10/site-packages/starlette/middleware/cors.py", line 146, in simple_response
    await self.app(scope, receive, send)
  File "/home/thrymr/.local/lib/python3.10/site-packages/starlette/middleware/exceptions.py", line 62, in __call__
    await wrap_app_handling_exceptions(self.app, conn)(scope, receive, send)
  File "/home/thrymr/.local/lib/python3.10/site-packages/starlette/_exception_handler.py", line 64, in wrapped_app
    raise exc
  File "/home/thrymr/.local/lib/python3.10/site-packages/starlette/_exception_handler.py", line 53, in wrapped_app
    await app(scope, receive, sender)
  File "/home/thrymr/.local/lib/python3.10/site-packages/starlette/routing.py", line 758, in __call__
    await self.middleware_stack(scope, receive, send)
  File "/home/thrymr/.local/lib/python3.10/site-packages/starlette/routing.py", line 778, in app
    await route.handle(scope, receive, send)
  File "/home/thrymr/.local/lib/python3.10/site-packages/starlette/routing.py", line 299, in handle
    await self.app(scope, receive, send)
  File "/home/thrymr/.local/lib/python3.10/site-packages/starlette/routing.py", line 79, in app
    await wrap_app_handling_exceptions(app, request)(scope, receive, send)
  File "/home/thrymr/.local/lib/python3.10/site-packages/starlette/_exception_handler.py", line 64, in wrapped_app
    raise exc
  File "/home/thrymr/.local/lib/python3.10/site-packages/starlette/_exception_handler.py", line 53, in wrapped_app
    await app(scope, receive, sender)
  File "/home/thrymr/.local/lib/python3.10/site-packages/starlette/routing.py", line 74, in app
    response = await func(request)
  File "/home/thrymr/.local/lib/python3.10/site-packages/fastapi/routing.py", line 317, in app
    raise FastAPIError(
fastapi.exceptions.FastAPIError: No response object was returned. There's a high chance that the application code is raising an exception and a dependency with yield has a block with a bare except, or a block with except Exception, and is not raising the exception again. Read more about it in the docs: https://fastapi.tiangolo.com/tutorial/dependencies/dependencies-with-yield/#dependencies-with-yield-and-except
2024-04-19 14:46:00,990-INFO-Shutting down
2024-04-19 14:46:01,090-INFO-Waiting for application shutdown.
2024-04-19 14:46:01,091-INFO-Application shutdown complete.
2024-04-19 14:46:01,091-INFO-Finished server process [75814]
2024-04-19 14:46:02,269-INFO-Started server process [80517]
2024-04-19 14:46:02,270-INFO-Waiting for application startup.
2024-04-19 14:46:02,270-INFO-Application startup complete.
2024-04-19 14:46:03,720-ERROR-Exception in ASGI application
Traceback (most recent call last):
  File "/home/thrymr/.local/lib/python3.10/site-packages/uvicorn/protocols/http/httptools_impl.py", line 376, in run_asgi
    result = await app(self.scope, self.receive, self.send)
  File "/home/thrymr/.local/lib/python3.10/site-packages/uvicorn/middleware/proxy_headers.py", line 75, in __call__
    return await self.app(scope, receive, send)
  File "/home/thrymr/.local/lib/python3.10/site-packages/fastapi/applications.py", line 1054, in __call__
    await super().__call__(scope, receive, send)
  File "/home/thrymr/.local/lib/python3.10/site-packages/starlette/applications.py", line 123, in __call__
    await self.middleware_stack(scope, receive, send)
  File "/home/thrymr/.local/lib/python3.10/site-packages/starlette/middleware/errors.py", line 186, in __call__
    raise exc
  File "/home/thrymr/.local/lib/python3.10/site-packages/starlette/middleware/errors.py", line 164, in __call__
    await self.app(scope, receive, _send)
  File "/home/thrymr/.local/lib/python3.10/site-packages/starlette/middleware/cors.py", line 91, in __call__
    await self.simple_response(scope, receive, send, request_headers=headers)
  File "/home/thrymr/.local/lib/python3.10/site-packages/starlette/middleware/cors.py", line 146, in simple_response
    await self.app(scope, receive, send)
  File "/home/thrymr/.local/lib/python3.10/site-packages/starlette/middleware/exceptions.py", line 62, in __call__
    await wrap_app_handling_exceptions(self.app, conn)(scope, receive, send)
  File "/home/thrymr/.local/lib/python3.10/site-packages/starlette/_exception_handler.py", line 64, in wrapped_app
    raise exc
  File "/home/thrymr/.local/lib/python3.10/site-packages/starlette/_exception_handler.py", line 53, in wrapped_app
    await app(scope, receive, sender)
  File "/home/thrymr/.local/lib/python3.10/site-packages/starlette/routing.py", line 758, in __call__
    await self.middleware_stack(scope, receive, send)
  File "/home/thrymr/.local/lib/python3.10/site-packages/starlette/routing.py", line 778, in app
    await route.handle(scope, receive, send)
  File "/home/thrymr/.local/lib/python3.10/site-packages/starlette/routing.py", line 299, in handle
    await self.app(scope, receive, send)
  File "/home/thrymr/.local/lib/python3.10/site-packages/starlette/routing.py", line 79, in app
    await wrap_app_handling_exceptions(app, request)(scope, receive, send)
  File "/home/thrymr/.local/lib/python3.10/site-packages/starlette/_exception_handler.py", line 64, in wrapped_app
    raise exc
  File "/home/thrymr/.local/lib/python3.10/site-packages/starlette/_exception_handler.py", line 53, in wrapped_app
    await app(scope, receive, sender)
  File "/home/thrymr/.local/lib/python3.10/site-packages/starlette/routing.py", line 74, in app
    response = await func(request)
  File "/home/thrymr/.local/lib/python3.10/site-packages/fastapi/routing.py", line 317, in app
    raise FastAPIError(
fastapi.exceptions.FastAPIError: No response object was returned. There's a high chance that the application code is raising an exception and a dependency with yield has a block with a bare except, or a block with except Exception, and is not raising the exception again. Read more about it in the docs: https://fastapi.tiangolo.com/tutorial/dependencies/dependencies-with-yield/#dependencies-with-yield-and-except
2024-04-19 14:48:58,946-INFO-Shutting down
2024-04-19 14:48:59,047-INFO-Waiting for application shutdown.
2024-04-19 14:48:59,048-INFO-Application shutdown complete.
2024-04-19 14:48:59,048-INFO-Finished server process [80517]
2024-04-19 14:55:22,352-INFO-Started server process [81131]
2024-04-19 14:55:22,353-INFO-Waiting for application startup.
2024-04-19 14:55:22,353-INFO-Application startup complete.
2024-04-19 14:56:49,594-INFO-Shutting down
2024-04-19 14:56:49,694-INFO-Waiting for application shutdown.
2024-04-19 14:56:49,695-INFO-Application shutdown complete.
2024-04-19 14:56:49,695-INFO-Finished server process [81131]
2024-04-19 14:57:56,023-INFO-Started server process [81262]
2024-04-19 14:57:56,023-INFO-Waiting for application startup.
2024-04-19 14:57:56,024-INFO-Application startup complete.
2024-04-19 15:08:46,780-INFO-Shutting down
2024-04-19 15:08:46,881-INFO-Waiting for application shutdown.
2024-04-19 15:08:46,881-INFO-Application shutdown complete.
2024-04-19 15:08:46,882-INFO-Finished server process [81262]
2024-04-19 15:08:48,054-INFO-Started server process [81914]
2024-04-19 15:08:48,055-INFO-Waiting for application startup.
2024-04-19 15:08:48,055-INFO-Application startup complete.
2024-04-19 15:11:02,800-INFO-Shutting down
2024-04-19 15:11:02,901-INFO-Waiting for application shutdown.
2024-04-19 15:11:02,902-INFO-Application shutdown complete.
2024-04-19 15:11:02,902-INFO-Finished server process [81914]
2024-04-19 15:11:03,975-INFO-Started server process [82045]
2024-04-19 15:11:03,975-INFO-Waiting for application startup.
2024-04-19 15:11:03,976-INFO-Application startup complete.
2024-04-19 15:11:15,603-INFO-Shutting down
2024-04-19 15:11:15,704-INFO-Waiting for application shutdown.
2024-04-19 15:11:15,705-INFO-Application shutdown complete.
2024-04-19 15:11:15,705-INFO-Finished server process [82045]
2024-04-19 15:11:16,865-INFO-Started server process [82068]
2024-04-19 15:11:16,865-INFO-Waiting for application startup.
2024-04-19 15:11:16,865-INFO-Application startup complete.
2024-04-19 15:11:27,390-INFO-Shutting down
2024-04-19 15:11:27,490-INFO-Waiting for application shutdown.
2024-04-19 15:11:27,491-INFO-Application shutdown complete.
2024-04-19 15:11:27,491-INFO-Finished server process [82068]
2024-04-19 15:11:28,604-INFO-Started server process [82089]
2024-04-19 15:11:28,604-INFO-Waiting for application startup.
2024-04-19 15:11:28,605-INFO-Application startup complete.
2024-04-19 15:12:34,978-ERROR-Exception in ASGI application
Traceback (most recent call last):
  File "/home/thrymr/.local/lib/python3.10/site-packages/uvicorn/protocols/http/httptools_impl.py", line 376, in run_asgi
    result = await app(self.scope, self.receive, self.send)
  File "/home/thrymr/.local/lib/python3.10/site-packages/uvicorn/middleware/proxy_headers.py", line 75, in __call__
    return await self.app(scope, receive, send)
  File "/home/thrymr/.local/lib/python3.10/site-packages/fastapi/applications.py", line 1054, in __call__
    await super().__call__(scope, receive, send)
  File "/home/thrymr/.local/lib/python3.10/site-packages/starlette/applications.py", line 123, in __call__
    await self.middleware_stack(scope, receive, send)
  File "/home/thrymr/.local/lib/python3.10/site-packages/starlette/middleware/errors.py", line 186, in __call__
    raise exc
  File "/home/thrymr/.local/lib/python3.10/site-packages/starlette/middleware/errors.py", line 164, in __call__
    await self.app(scope, receive, _send)
  File "/home/thrymr/.local/lib/python3.10/site-packages/starlette/middleware/cors.py", line 91, in __call__
    await self.simple_response(scope, receive, send, request_headers=headers)
  File "/home/thrymr/.local/lib/python3.10/site-packages/starlette/middleware/cors.py", line 146, in simple_response
    await self.app(scope, receive, send)
  File "/home/thrymr/.local/lib/python3.10/site-packages/starlette/middleware/exceptions.py", line 62, in __call__
    await wrap_app_handling_exceptions(self.app, conn)(scope, receive, send)
  File "/home/thrymr/.local/lib/python3.10/site-packages/starlette/_exception_handler.py", line 64, in wrapped_app
    raise exc
  File "/home/thrymr/.local/lib/python3.10/site-packages/starlette/_exception_handler.py", line 53, in wrapped_app
    await app(scope, receive, sender)
  File "/home/thrymr/.local/lib/python3.10/site-packages/starlette/routing.py", line 758, in __call__
    await self.middleware_stack(scope, receive, send)
  File "/home/thrymr/.local/lib/python3.10/site-packages/starlette/routing.py", line 778, in app
    await route.handle(scope, receive, send)
  File "/home/thrymr/.local/lib/python3.10/site-packages/starlette/routing.py", line 299, in handle
    await self.app(scope, receive, send)
  File "/home/thrymr/.local/lib/python3.10/site-packages/starlette/routing.py", line 79, in app
    await wrap_app_handling_exceptions(app, request)(scope, receive, send)
  File "/home/thrymr/.local/lib/python3.10/site-packages/starlette/_exception_handler.py", line 64, in wrapped_app
    raise exc
  File "/home/thrymr/.local/lib/python3.10/site-packages/starlette/_exception_handler.py", line 53, in wrapped_app
    await app(scope, receive, sender)
  File "/home/thrymr/.local/lib/python3.10/site-packages/starlette/routing.py", line 74, in app
    response = await func(request)
  File "/home/thrymr/.local/lib/python3.10/site-packages/fastapi/routing.py", line 317, in app
    raise FastAPIError(
fastapi.exceptions.FastAPIError: No response object was returned. There's a high chance that the application code is raising an exception and a dependency with yield has a block with a bare except, or a block with except Exception, and is not raising the exception again. Read more about it in the docs: https://fastapi.tiangolo.com/tutorial/dependencies/dependencies-with-yield/#dependencies-with-yield-and-except
2024-04-19 15:26:58,320-INFO-Shutting down
2024-04-19 15:26:58,420-INFO-Waiting for application shutdown.
2024-04-19 15:26:58,421-INFO-Application shutdown complete.
2024-04-19 15:26:58,421-INFO-Finished server process [82089]
2024-04-19 15:42:36,836-INFO-Started server process [84103]
2024-04-19 15:42:36,836-INFO-Waiting for application startup.
2024-04-19 15:42:36,837-INFO-Application startup complete.
2024-04-19 15:45:23,326-INFO-Shutting down
2024-04-19 15:45:23,427-INFO-Waiting for application shutdown.
2024-04-19 15:45:23,428-INFO-Application shutdown complete.
2024-04-19 15:45:23,428-INFO-Finished server process [84103]
2024-04-22 11:48:37,948-INFO-Started server process [244565]
2024-04-22 11:48:37,949-INFO-Waiting for application startup.
2024-04-22 11:48:37,949-INFO-Application startup complete.
2024-04-22 11:49:28,341-ERROR-Exception in ASGI application
Traceback (most recent call last):
  File "/home/thrymr/.local/lib/python3.10/site-packages/uvicorn/protocols/http/httptools_impl.py", line 376, in run_asgi
    result = await app(self.scope, self.receive, self.send)
  File "/home/thrymr/.local/lib/python3.10/site-packages/uvicorn/middleware/proxy_headers.py", line 75, in __call__
    return await self.app(scope, receive, send)
  File "/home/thrymr/.local/lib/python3.10/site-packages/fastapi/applications.py", line 1054, in __call__
    await super().__call__(scope, receive, send)
  File "/home/thrymr/.local/lib/python3.10/site-packages/starlette/applications.py", line 123, in __call__
    await self.middleware_stack(scope, receive, send)
  File "/home/thrymr/.local/lib/python3.10/site-packages/starlette/middleware/errors.py", line 186, in __call__
    raise exc
  File "/home/thrymr/.local/lib/python3.10/site-packages/starlette/middleware/errors.py", line 164, in __call__
    await self.app(scope, receive, _send)
  File "/home/thrymr/.local/lib/python3.10/site-packages/starlette/middleware/cors.py", line 91, in __call__
    await self.simple_response(scope, receive, send, request_headers=headers)
  File "/home/thrymr/.local/lib/python3.10/site-packages/starlette/middleware/cors.py", line 146, in simple_response
    await self.app(scope, receive, send)
  File "/home/thrymr/.local/lib/python3.10/site-packages/starlette/middleware/exceptions.py", line 62, in __call__
    await wrap_app_handling_exceptions(self.app, conn)(scope, receive, send)
  File "/home/thrymr/.local/lib/python3.10/site-packages/starlette/_exception_handler.py", line 64, in wrapped_app
    raise exc
  File "/home/thrymr/.local/lib/python3.10/site-packages/starlette/_exception_handler.py", line 53, in wrapped_app
    await app(scope, receive, sender)
  File "/home/thrymr/.local/lib/python3.10/site-packages/starlette/routing.py", line 758, in __call__
    await self.middleware_stack(scope, receive, send)
  File "/home/thrymr/.local/lib/python3.10/site-packages/starlette/routing.py", line 778, in app
    await route.handle(scope, receive, send)
  File "/home/thrymr/.local/lib/python3.10/site-packages/starlette/routing.py", line 299, in handle
    await self.app(scope, receive, send)
  File "/home/thrymr/.local/lib/python3.10/site-packages/starlette/routing.py", line 79, in app
    await wrap_app_handling_exceptions(app, request)(scope, receive, send)
  File "/home/thrymr/.local/lib/python3.10/site-packages/starlette/_exception_handler.py", line 64, in wrapped_app
    raise exc
  File "/home/thrymr/.local/lib/python3.10/site-packages/starlette/_exception_handler.py", line 53, in wrapped_app
    await app(scope, receive, sender)
  File "/home/thrymr/.local/lib/python3.10/site-packages/starlette/routing.py", line 74, in app
    response = await func(request)
  File "/home/thrymr/.local/lib/python3.10/site-packages/fastapi/routing.py", line 317, in app
    raise FastAPIError(
fastapi.exceptions.FastAPIError: No response object was returned. There's a high chance that the application code is raising an exception and a dependency with yield has a block with a bare except, or a block with except Exception, and is not raising the exception again. Read more about it in the docs: https://fastapi.tiangolo.com/tutorial/dependencies/dependencies-with-yield/#dependencies-with-yield-and-except
2024-04-22 11:52:39,288-INFO-Shutting down
2024-04-22 11:52:39,389-INFO-Waiting for application shutdown.
2024-04-22 11:52:39,390-INFO-Application shutdown complete.
2024-04-22 11:52:39,390-INFO-Finished server process [244565]
2024-04-22 11:52:44,783-INFO-Started server process [244830]
2024-04-22 11:52:44,784-INFO-Waiting for application startup.
2024-04-22 11:52:44,784-INFO-Application startup complete.
2024-04-22 12:29:26,250-INFO-Shutting down
2024-04-22 12:29:26,351-INFO-Waiting for application shutdown.
2024-04-22 12:29:26,352-INFO-Application shutdown complete.
2024-04-22 12:29:26,352-INFO-Finished server process [244830]
2024-04-22 12:29:27,481-INFO-Started server process [246559]
2024-04-22 12:29:27,481-INFO-Waiting for application startup.
2024-04-22 12:29:27,481-INFO-Application startup complete.
2024-04-22 12:30:48,896-INFO-Shutting down
2024-04-22 12:30:48,997-INFO-Waiting for application shutdown.
2024-04-22 12:30:48,997-INFO-Application shutdown complete.
2024-04-22 12:30:48,997-INFO-Finished server process [246559]
2024-04-22 12:30:50,065-INFO-Started server process [246656]
2024-04-22 12:30:50,065-INFO-Waiting for application startup.
2024-04-22 12:30:50,065-INFO-Application startup complete.
2024-04-22 12:33:49,318-INFO-Shutting down
2024-04-22 12:33:49,419-INFO-Waiting for application shutdown.
2024-04-22 12:33:49,420-INFO-Application shutdown complete.
2024-04-22 12:33:49,420-INFO-Finished server process [246656]
2024-04-22 12:33:50,506-INFO-Started server process [246860]
2024-04-22 12:33:50,507-INFO-Waiting for application startup.
2024-04-22 12:33:50,507-INFO-Application startup complete.
2024-04-22 12:34:55,581-INFO-Shutting down
2024-04-22 12:34:55,681-INFO-Waiting for application shutdown.
2024-04-22 12:34:55,682-INFO-Application shutdown complete.
2024-04-22 12:34:55,682-INFO-Finished server process [246860]
2024-04-22 12:34:56,729-INFO-Started server process [246958]
2024-04-22 12:34:56,729-INFO-Waiting for application startup.
2024-04-22 12:34:56,729-INFO-Application startup complete.
2024-04-22 12:38:46,328-INFO-Shutting down
2024-04-22 12:38:46,428-INFO-Waiting for application shutdown.
2024-04-22 12:38:46,429-INFO-Application shutdown complete.
2024-04-22 12:38:46,429-INFO-Finished server process [246958]
2024-04-22 12:42:35,731-INFO-Started server process [247436]
2024-04-22 12:42:35,731-INFO-Waiting for application startup.
2024-04-22 12:42:35,732-INFO-Application startup complete.
2024-04-22 12:44:01,375-INFO-Shutting down
2024-04-22 12:44:01,476-INFO-Waiting for application shutdown.
2024-04-22 12:44:01,476-INFO-Application shutdown complete.
2024-04-22 12:44:01,476-INFO-Finished server process [247436]
2024-04-22 12:44:02,519-INFO-Started server process [247519]
2024-04-22 12:44:02,519-INFO-Waiting for application startup.
2024-04-22 12:44:02,520-INFO-Application startup complete.
2024-04-22 12:44:34,514-INFO-Shutting down
2024-04-22 12:44:34,615-INFO-Waiting for application shutdown.
2024-04-22 12:44:34,615-INFO-Application shutdown complete.
2024-04-22 12:44:34,616-INFO-Finished server process [247519]
2024-04-22 12:44:35,683-INFO-Started server process [247557]
2024-04-22 12:44:35,683-INFO-Waiting for application startup.
2024-04-22 12:44:35,683-INFO-Application startup complete.
2024-04-22 12:44:41,437-ERROR-Email already exists
2024-04-22 12:44:48,719-INFO-Shutting down
2024-04-22 12:44:48,820-INFO-Waiting for application shutdown.
2024-04-22 12:44:48,820-INFO-Application shutdown complete.
2024-04-22 12:44:48,820-INFO-Finished server process [247557]
2024-04-22 12:46:20,709-INFO-Started server process [247709]
2024-04-22 12:46:20,709-INFO-Waiting for application startup.
2024-04-22 12:46:20,710-INFO-Application startup complete.
2024-04-22 12:56:18,644-ERROR-Email already exists
2024-04-22 12:58:18,108-INFO-Shutting down
2024-04-22 12:58:18,209-INFO-Waiting for application shutdown.
2024-04-22 12:58:18,210-INFO-Application shutdown complete.
2024-04-22 12:58:18,210-INFO-Finished server process [247709]
2024-04-22 12:58:19,332-INFO-Started server process [248345]
2024-04-22 12:58:19,332-INFO-Waiting for application startup.
2024-04-22 12:58:19,333-INFO-Application startup complete.
2024-04-22 13:06:42,419-INFO-Shutting down
2024-04-22 13:06:42,520-INFO-Waiting for application shutdown.
2024-04-22 13:06:42,521-INFO-Application shutdown complete.
2024-04-22 13:06:42,521-INFO-Finished server process [248345]
2024-04-22 13:06:43,670-INFO-Started server process [248671]
2024-04-22 13:06:43,671-INFO-Waiting for application startup.
2024-04-22 13:06:43,671-INFO-Application startup complete.
2024-04-22 13:12:23,524-INFO-Shutting down
2024-04-22 13:12:23,625-INFO-Waiting for application shutdown.
2024-04-22 13:12:23,625-INFO-Application shutdown complete.
2024-04-22 13:12:23,625-INFO-Finished server process [248671]
2024-04-22 13:12:24,731-INFO-Started server process [249541]
2024-04-22 13:12:24,731-INFO-Waiting for application startup.
2024-04-22 13:12:24,731-INFO-Application startup complete.
2024-04-22 13:13:48,236-INFO-Shutting down
2024-04-22 13:13:48,337-INFO-Waiting for application shutdown.
2024-04-22 13:13:48,337-INFO-Application shutdown complete.
2024-04-22 13:13:48,338-INFO-Finished server process [249541]
2024-04-22 13:13:49,433-INFO-Started server process [249639]
2024-04-22 13:13:49,433-INFO-Waiting for application startup.
2024-04-22 13:13:49,433-INFO-Application startup complete.
2024-04-22 13:18:24,921-INFO-Shutting down
2024-04-22 13:18:25,022-INFO-Waiting for application shutdown.
2024-04-22 13:18:25,023-INFO-Application shutdown complete.
2024-04-22 13:18:25,023-INFO-Finished server process [249639]
2024-04-22 13:18:26,111-INFO-Started server process [249836]
2024-04-22 13:18:26,111-INFO-Waiting for application startup.
2024-04-22 13:18:26,112-INFO-Application startup complete.
2024-04-22 13:25:40,775-INFO-Shutting down
2024-04-22 13:25:40,875-INFO-Waiting for application shutdown.
2024-04-22 13:25:40,876-INFO-Application shutdown complete.
2024-04-22 13:25:40,876-INFO-Finished server process [249836]
2024-04-22 13:25:42,020-INFO-Started server process [250143]
2024-04-22 13:25:42,021-INFO-Waiting for application startup.
2024-04-22 13:25:42,021-INFO-Application startup complete.
2024-04-22 13:30:04,784-INFO-Shutting down
2024-04-22 13:30:04,885-INFO-Waiting for application shutdown.
2024-04-22 13:30:04,886-INFO-Application shutdown complete.
2024-04-22 13:30:04,886-INFO-Finished server process [250143]
2024-04-22 13:30:06,002-INFO-Started server process [250379]
2024-04-22 13:30:06,002-INFO-Waiting for application startup.
2024-04-22 13:30:06,003-INFO-Application startup complete.
2024-04-22 13:38:25,227-INFO-Shutting down
2024-04-22 13:38:25,329-INFO-Waiting for application shutdown.
2024-04-22 13:38:25,329-INFO-Application shutdown complete.
2024-04-22 13:38:25,330-INFO-Finished server process [250379]
2024-04-22 13:38:26,415-INFO-Started server process [250892]
2024-04-22 13:38:26,416-INFO-Waiting for application startup.
2024-04-22 13:38:26,416-INFO-Application startup complete.
2024-04-22 13:45:27,673-INFO-Shutting down
2024-04-22 13:45:27,774-INFO-Waiting for application shutdown.
2024-04-22 13:45:27,774-INFO-Application shutdown complete.
2024-04-22 13:45:27,774-INFO-Finished server process [250892]
2024-04-22 13:45:28,928-INFO-Started server process [251402]
2024-04-22 13:45:28,929-INFO-Waiting for application startup.
2024-04-22 13:45:28,929-INFO-Application startup complete.
2024-04-22 13:55:40,596-INFO-Shutting down
2024-04-22 13:55:40,697-INFO-Waiting for application shutdown.
2024-04-22 13:55:40,698-INFO-Application shutdown complete.
2024-04-22 13:55:40,698-INFO-Finished server process [251402]
2024-04-22 13:55:41,782-INFO-Started server process [251979]
2024-04-22 13:55:41,782-INFO-Waiting for application startup.
2024-04-22 13:55:41,783-INFO-Application startup complete.
2024-04-22 14:51:43,831-INFO-Shutting down
2024-04-22 14:51:43,932-INFO-Waiting for application shutdown.
2024-04-22 14:51:43,933-INFO-Application shutdown complete.
2024-04-22 14:51:43,933-INFO-Finished server process [251979]
2024-04-22 14:55:00,720-INFO-Started server process [255258]
2024-04-22 14:55:00,720-INFO-Waiting for application startup.
2024-04-22 14:55:00,720-INFO-Application startup complete.
2024-04-22 14:55:38,720-INFO-Shutting down
2024-04-22 14:55:38,821-INFO-Waiting for application shutdown.
2024-04-22 14:55:38,822-INFO-Application shutdown complete.
2024-04-22 14:55:38,822-INFO-Finished server process [255258]
2024-04-22 14:58:05,320-INFO-Started server process [255461]
2024-04-22 14:58:05,320-INFO-Waiting for application startup.
2024-04-22 14:58:05,320-INFO-Application startup complete.
2024-04-22 14:59:25,441-INFO-User signed up successfully
2024-04-22 15:03:42,522-INFO-Shutting down
2024-04-22 15:03:42,623-INFO-Waiting for application shutdown.
2024-04-22 15:03:42,624-INFO-Application shutdown complete.
2024-04-22 15:03:42,624-INFO-Finished server process [255461]
2024-04-22 15:03:43,792-INFO-Started server process [255801]
2024-04-22 15:03:43,793-INFO-Waiting for application startup.
2024-04-22 15:03:43,793-INFO-Application startup complete.
2024-04-22 15:11:48,638-INFO-Shutting down
2024-04-22 15:11:48,739-INFO-Waiting for application shutdown.
2024-04-22 15:11:48,740-INFO-Application shutdown complete.
2024-04-22 15:11:48,740-INFO-Finished server process [255801]
2024-04-22 15:11:49,860-INFO-Started server process [256608]
2024-04-22 15:11:49,861-INFO-Waiting for application startup.
2024-04-22 15:11:49,861-INFO-Application startup complete.
2024-04-22 15:13:00,551-INFO-Shutting down
2024-04-22 15:13:00,651-INFO-Waiting for application shutdown.
2024-04-22 15:13:00,652-INFO-Application shutdown complete.
2024-04-22 15:13:00,653-INFO-Finished server process [256608]
2024-04-22 15:13:01,766-INFO-Started server process [256690]
2024-04-22 15:13:01,766-INFO-Waiting for application startup.
2024-04-22 15:13:01,767-INFO-Application startup complete.
2024-04-22 15:13:51,594-INFO-Shutting down
2024-04-22 15:13:51,694-INFO-Waiting for application shutdown.
2024-04-22 15:13:51,694-INFO-Application shutdown complete.
2024-04-22 15:13:51,695-INFO-Finished server process [256690]
2024-04-22 15:13:52,838-INFO-Started server process [256776]
2024-04-22 15:13:52,838-INFO-Waiting for application startup.
2024-04-22 15:13:52,838-INFO-Application startup complete.
2024-04-22 15:15:57,010-INFO-Starting login process...
2024-04-22 15:20:15,665-INFO-Shutting down
2024-04-22 15:20:15,766-INFO-Waiting for application shutdown.
2024-04-22 15:20:15,767-INFO-Application shutdown complete.
2024-04-22 15:20:15,767-INFO-Finished server process [256776]
2024-04-22 15:20:17,024-INFO-Started server process [257242]
2024-04-22 15:20:17,024-INFO-Waiting for application startup.
2024-04-22 15:20:17,024-INFO-Application startup complete.
2024-04-22 15:20:44,389-INFO-Shutting down
2024-04-22 15:20:44,489-INFO-Waiting for application shutdown.
2024-04-22 15:20:44,489-INFO-Application shutdown complete.
2024-04-22 15:20:44,490-INFO-Finished server process [257242]
2024-04-22 15:24:17,106-INFO-Started server process [257576]
2024-04-22 15:24:17,107-INFO-Waiting for application startup.
2024-04-22 15:24:17,107-INFO-Application startup complete.
2024-04-22 15:24:24,320-INFO-Starting login process...
2024-04-22 15:30:58,948-INFO-Shutting down
2024-04-22 15:30:59,049-INFO-Waiting for application shutdown.
2024-04-22 15:30:59,049-INFO-Application shutdown complete.
2024-04-22 15:30:59,049-INFO-Finished server process [257576]
2024-04-22 15:31:00,171-INFO-Started server process [258145]
2024-04-22 15:31:00,171-INFO-Waiting for application startup.
2024-04-22 15:31:00,171-INFO-Application startup complete.
2024-04-22 15:31:05,756-INFO-Starting login process...
2024-04-22 15:31:52,279-INFO-Shutting down
2024-04-22 15:31:52,381-INFO-Waiting for application shutdown.
2024-04-22 15:31:52,381-INFO-Application shutdown complete.
2024-04-22 15:31:52,381-INFO-Finished server process [258145]
2024-04-22 15:31:53,574-INFO-Started server process [258246]
2024-04-22 15:31:53,574-INFO-Waiting for application startup.
2024-04-22 15:31:53,574-INFO-Application startup complete.
2024-04-22 15:31:54,160-INFO-Starting login process...
2024-04-22 15:34:37,234-INFO-User signed up successfully
2024-04-22 15:36:12,663-INFO-Shutting down
2024-04-22 15:36:12,763-INFO-Waiting for application shutdown.
2024-04-22 15:36:12,764-INFO-Application shutdown complete.
2024-04-22 15:36:12,764-INFO-Finished server process [258246]
2024-04-22 15:38:06,713-INFO-Started server process [258840]
2024-04-22 15:38:06,713-INFO-Waiting for application startup.
2024-04-22 15:38:06,714-INFO-Application startup complete.
2024-04-22 15:38:50,420-INFO-Starting login process...
2024-04-22 15:38:50,744-INFO-Generating access token
2024-04-22 18:44:29,666-INFO-Shutting down
2024-04-22 18:44:29,767-INFO-Waiting for application shutdown.
2024-04-22 18:44:29,767-INFO-Application shutdown complete.
2024-04-22 18:44:29,768-INFO-Finished server process [258840]
2024-04-22 18:44:30,862-INFO-Started server process [274369]
2024-04-22 18:44:30,863-INFO-Waiting for application startup.
2024-04-22 18:44:30,863-INFO-Application startup complete.
2024-04-22 18:44:38,449-INFO-Starting login process...
2024-04-22 18:44:38,756-INFO-Generating access token
2024-04-22 18:45:24,748-INFO-Starting login process...
2024-04-22 18:45:25,007-INFO-Generating access token
2024-04-22 18:47:12,098-INFO-Shutting down
2024-04-22 18:47:12,199-INFO-Waiting for application shutdown.
2024-04-22 18:47:12,200-INFO-Application shutdown complete.
2024-04-22 18:47:12,201-INFO-Finished server process [274369]
2024-04-22 18:47:14,497-INFO-Started server process [274626]
2024-04-22 18:47:14,498-INFO-Waiting for application startup.
2024-04-22 18:47:14,498-INFO-Application startup complete.
2024-04-22 18:47:20,718-INFO-Starting login process...
2024-04-22 18:47:21,024-INFO-Generating access token
2024-04-22 18:49:45,098-INFO-Shutting down
2024-04-22 18:49:45,199-INFO-Waiting for application shutdown.
2024-04-22 18:49:45,199-INFO-Application shutdown complete.
2024-04-22 18:49:45,200-INFO-Finished server process [274626]
2024-04-22 18:49:46,303-INFO-Started server process [274880]
2024-04-22 18:49:46,303-INFO-Waiting for application startup.
2024-04-22 18:49:46,303-INFO-Application startup complete.
2024-04-22 18:50:13,774-INFO-Shutting down
2024-04-22 18:50:13,875-INFO-Waiting for application shutdown.
2024-04-22 18:50:13,875-INFO-Application shutdown complete.
2024-04-22 18:50:13,876-INFO-Finished server process [274880]
2024-04-22 18:50:14,936-INFO-Started server process [274927]
2024-04-22 18:50:14,936-INFO-Waiting for application startup.
2024-04-22 18:50:14,936-INFO-Application startup complete.
2024-04-22 18:50:17,121-INFO-Starting login process...
2024-04-22 18:50:17,434-INFO-Generating access token
2024-04-22 18:51:17,291-INFO-Shutting down
2024-04-22 18:51:17,392-INFO-Waiting for application shutdown.
2024-04-22 18:51:17,393-INFO-Application shutdown complete.
2024-04-22 18:51:17,393-INFO-Finished server process [274927]
2024-04-22 18:51:18,491-INFO-Started server process [275046]
2024-04-22 18:51:18,491-INFO-Waiting for application startup.
2024-04-22 18:51:18,491-INFO-Application startup complete.
2024-04-22 18:52:38,296-INFO-Shutting down
2024-04-22 18:52:38,397-INFO-Waiting for application shutdown.
2024-04-22 18:52:38,397-INFO-Application shutdown complete.
2024-04-22 18:52:38,398-INFO-Finished server process [275046]
2024-04-22 18:52:39,507-INFO-Started server process [275164]
2024-04-22 18:52:39,508-INFO-Waiting for application startup.
2024-04-22 18:52:39,508-INFO-Application startup complete.
2024-04-22 18:53:11,463-INFO-Starting login process...
2024-04-22 18:53:11,818-INFO-Generating access token
2024-04-22 18:56:29,646-INFO-Shutting down
2024-04-22 18:56:29,747-INFO-Waiting for application shutdown.
2024-04-22 18:56:29,748-INFO-Application shutdown complete.
2024-04-22 18:56:29,748-INFO-Finished server process [275164]
2024-04-22 18:56:30,828-INFO-Started server process [275515]
2024-04-22 18:56:30,828-INFO-Waiting for application startup.
2024-04-22 18:56:30,828-INFO-Application startup complete.
2024-04-22 18:57:00,208-INFO-Shutting down
2024-04-22 18:57:00,308-INFO-Waiting for application shutdown.
2024-04-22 18:57:00,309-INFO-Application shutdown complete.
2024-04-22 18:57:00,310-INFO-Finished server process [275515]
2024-04-22 18:57:01,398-INFO-Started server process [275572]
2024-04-22 18:57:01,398-INFO-Waiting for application startup.
2024-04-22 18:57:01,399-INFO-Application startup complete.
2024-04-22 18:57:34,694-INFO-Shutting down
2024-04-22 18:57:34,794-INFO-Waiting for application shutdown.
2024-04-22 18:57:34,795-INFO-Application shutdown complete.
2024-04-22 18:57:34,795-INFO-Finished server process [275572]
2024-04-22 18:57:37,785-INFO-Started server process [275644]
2024-04-22 18:57:37,785-INFO-Waiting for application startup.
2024-04-22 18:57:37,786-INFO-Application startup complete.
2024-04-22 18:57:47,869-INFO-Starting login process...
2024-04-22 18:57:48,157-INFO-Generating access token
2024-04-22 18:58:56,130-INFO-Shutting down
2024-04-22 18:58:56,230-INFO-Waiting for application shutdown.
2024-04-22 18:58:56,231-INFO-Application shutdown complete.
2024-04-22 18:58:56,231-INFO-Finished server process [275644]
2024-04-22 18:58:57,311-INFO-Started server process [275779]
2024-04-22 18:58:57,311-INFO-Waiting for application startup.
2024-04-22 18:58:57,312-INFO-Application startup complete.
2024-04-22 18:59:50,654-INFO-Shutting down
2024-04-22 18:59:50,755-INFO-Finished server process [275779]
2024-04-22 18:59:50,763-ERROR-Traceback (most recent call last):
  File "/home/thrymr/.local/lib/python3.10/site-packages/starlette/routing.py", line 743, in lifespan
    await receive()
  File "/home/thrymr/.local/lib/python3.10/site-packages/uvicorn/lifespan/on.py", line 135, in receive
    return await self.receive_queue.get()
  File "/usr/lib/python3.10/asyncio/queues.py", line 159, in get
    await getter
asyncio.exceptions.CancelledError

